Workbook

Sheet Daten
A1: Turniername | D1: Saison | E1: Bowlinganlage | F1: Bahnwechsel | G1: Importmöglichkeiten | H1: Registerfarben | I1: Ja/Nein | J1: Gruppe
A2: BM Jugend Einzel | B2: 2023 | C2: 2024 | D2: =CONCAT(B2,"/",C2) -> #N/A | E2: Bad Tölz Flint Bowling | F2: ganze Doppelbahn wechselt nach rechts | G2: Keine | H2: AH | I2: Ja | J2: Jugend A-männlich
A3: BM Jugend Doppel | B3: =B2+1 -> 2024 | C3: =C2+1 -> 2025 | D3: =CONCAT(B3,"/",C3) -> #N/A | E3: Bamberg Bowlinghaus | F3: Linke Bahne wechselt nach links, rechte Bahn wechselt nach rechts | G3: DPB | H3: Funktionär | I3: Nein | J3: Jugend A-weiblich
A4: BM Jugend Trio | B4: =B3+1 -> 2025 | C4: =C3+1 -> 2026 | D4: =CONCAT(B4,"/",C4) -> #N/A | E4: Bayreuth Blu Bowl | G4: Max Munich | H4: Funktionär/Auswerter | J4: Jugend B-männlich
A5: BM Jugend Masters | B5: =B4+1 -> 2026 | C5: =C4+1 -> 2027 | D5: =CONCAT(B5,"/",C5) -> #N/A | E5: Brunnthal Max Munich | H5: Eingabe Auswerter | J5: Jugend B-weiblich
A6: BM Jugend All Event | B6: =B5+1 -> 2027 | C6: =C5+1 -> 2028 | D6: =CONCAT(B6,"/",C6) -> #N/A | E6: Dettelbach Extreme Bowlingarena | H6: Ausgabe Ergebnisse | J6: Jugend C-männlich
A7: BM Herren Einzel | B7: =B6+1 -> 2028 | C7: =C6+1 -> 2029 | D7: =CONCAT(B7,"/",C7) -> #N/A | E7: Friedrichshafen Seaside | H7: Berechnungstabellen | J7: Jugend C-weiblich
A8: BM Herren Doppel | B8: =B7+1 -> 2029 | C8: =C7+1 -> 2030 | D8: =CONCAT(B8,"/",C8) -> #N/A | E8: Garmisch Zugspitzbowling | J8: Männer
A9: BM Damen Einzel | B9: =B8+1 -> 2030 | C9: =C8+1 -> 2031 | D9: =CONCAT(B9,"/",C9) -> #N/A | E9: Ingolstadt Cosmos Bowling Arena | J9: Frauen
A10: BM Damen Doppel | B10: =B9+1 -> 2031 | C10: =C9+1 -> 2032 | D10: =CONCAT(B10,"/",C10) -> #N/A | E10: Kempten Big Bowl | J10: Junioren
A11: BM Senioren Einzel | B11: =B10+1 -> 2032 | C11: =C10+1 -> 2033 | D11: =CONCAT(B11,"/",C11) -> #N/A | E11: Landshut LA-Bowling | J11: Juniorinnen
A12: BM Senioren Doppel | B12: =B11+1 -> 2033 | C12: =C11+1 -> 2034 | D12: =CONCAT(B12,"/",C12) -> #N/A | E12: München Hollywood Super Bowling | J12: Senioren A
A13: BM Senioren Trio | B13: =B12+1 -> 2034 | C13: =C12+1 -> 2035 | D13: =CONCAT(B13,"/",C13) -> #N/A | E13: München Isar Bowling | J13: Senioren B
A14: BM Versehrte Einzel | B14: =B13+1 -> 2035 | C14: =C13+1 -> 2036 | D14: =CONCAT(B14,"/",C14) -> #N/A | E14: Nürnberg West Bowl | J14: Senioren C
A15: BM Versehrte Doppel | B15: =B14+1 -> 2036 | C15: =C14+1 -> 2037 | D15: =CONCAT(B15,"/",C15) -> #N/A | E15: Olching 5005 Bowling | J15: Seniorinnen A
A16: BM Versehrte Trio | B16: =B15+1 -> 2037 | C16: =C15+1 -> 2038 | D16: =CONCAT(B16,"/",C16) -> #N/A | E16: Pfaffenhofen Hollywood Super Bowling | J16: Seniorinnen B
A17: BM Mixed Doppel | B17: =B16+1 -> 2038 | C17: =C16+1 -> 2039 | D17: =CONCAT(B17,"/",C17) -> #N/A | E17: Regensburg Super Bowl | J17: Seniorinnen C
A18: BM Junioren Einzel | B18: =B17+1 -> 2039 | C18: =C17+1 -> 2040 | D18: =CONCAT(B18,"/",C18) -> #N/A | E18: Rosenheim In(n) Bowling | J18: Versehrte H1
A19: BM Junioren Doppel | B19: =B18+1 -> 2040 | C19: =C18+1 -> 2041 | D19: =CONCAT(B19,"/",C19) -> #N/A | E19: Rottendorf Bowling-Center | J19: Versehrte DA
... A21: Nordbayerische Herren | B21: =B20+1 -> 2042 | C21: =C20+1 -> 2043 | D21: =CONCAT(B21,"/",C21) -> #N/A | E21: Schweinfurt Extreme Bowlingarena | J21: Seniorinnen B/C
B22: =B21+1 -> 2043 | C22: =C21+1 -> 2044 | D22: =CONCAT(B22,"/",C22) -> #N/A | E22: Unterföhring Dreambowl Palace
B23: =B22+1 -> 2044 | C23: =C22+1 -> 2045 | D23: =CONCAT(B23,"/",C23) -> #N/A | E23: Würzburg Midnight Bowling
B24: =B23+1 -> 2045 | C24: =C23+1 -> 2046 | D24: =CONCAT(B24,"/",C24) -> #N/A
B25: =B24+1 -> 2046 | C25: =C24+1 -> 2047 | D25: =CONCAT(B25,"/",C25) -> #N/A
B26: =B25+1 -> 2047 | C26: =C25+1 -> 2048 | D26: =CONCAT(B26,"/",C26) -> #N/A
B27: =B26+1 -> 2048 | C27: =C26+1 -> 2049 | D27: =CONCAT(B27,"/",C27) -> #N/A
B28: =B27+1 -> 2049 | C28: =C27+1 -> 2050 | D28: =CONCAT(B28,"/",C28) -> #N/A
B29: =B28+1 -> 2050 | C29: =C28+1 -> 2051 | D29: =CONCAT(B29,"/",C29) -> #N/A
B30: =B29+1 -> 2051 | C30: =C29+1 -> 2052 | D30: =CONCAT(B30,"/",C30) -> #N/A
B31: =B30+1 -> 2052 | C31: =C30+1 -> 2053 | D31: =CONCAT(B31,"/",C31) -> #N/A
B32: =B31+1 -> 2053 | C32: =C31+1 -> 2054 | D32: =CONCAT(B32,"/",C32) -> #N/A
B33: =B32+1 -> 2054 | C33: =C32+1 -> 2055 | D33: =CONCAT(B33,"/",C33) -> #N/A
B34: =B33+1 -> 2055 | C34: =C33+1 -> 2056 | D34: =CONCAT(B34,"/",C34) -> #N/A
B35: =B34+1 -> 2056 | C35: =C34+1 -> 2057 | D35: =CONCAT(B35,"/",C35) -> #N/A
... B50: =B49+1 -> 2071 | C50: =C49+1 -> 2072 | D50: =CONCAT(B50,"/",C50) -> #N/A

Sheet Mitglieder BBU
A1: EDV | B1: Passnummer | C1: Anrede | D1: Vorname | E1: Nachname | F1: Name | G1: Verein | H1: Club | I1: Ranglistenkarte | J1: AK | K1: Beitrag
A2: 7981 | B2: 125194 | C2: Frau | D2: Anita | E2: Baur | F2: Anita Baur | G2: 1. BSV Ulm/Neu-Ulm | H2: BC Murmels Neu-Ulm | I2: X | J2: Seniorinnen B | K2: Erwachsener
A3: 16024 | B3: 125183 | C3: Herr | D3: Timo | E3: Baumann | F3: Timo Baumann | G3: 1. BSV Ulm/Neu-Ulm | H3: BC Neu-Ulmer Falken | I3: X | J3: Männer | K3: Erwachsener
A4: 16051 | B4: 148840 | C4: Herr | D4: Daniel | E4: Baumann | F4: Daniel Baumann | G4: 1. BSV Ulm/Neu-Ulm | H4: BC Neu-Ulmer Falken | I4: X | J4: Männer | K4: Erwachsener
A5: 7245 | B5: 136420 | C5: Herr | D5: Bernd | E5: Bauhofer | F5: Bernd Bauhofer | G5: BSV Berchtesgaden e.V. | H5: BC Berchtesgaden | I5: X | J5: Senioren C | K5: Erwachsener
A6: 16861 | B6: 16489 | C6: Herr | D6: Simon | E6: Bauer | F6: Simon Bauer | G6: Rottendorfer BV 1984 e.V. | H6: SG-Rottendorf | I6: X | J6: Männer | K6: Erwachsener
A7: 16860 | B7: 16486 | C7: Herr | D7: Rudi | E7: Bauer | F7: Rudi Bauer | G7: Rottendorfer BV 1984 e.V. | H7: SG-Rottendorf | I7: X | J7: Senioren B | K7: Erwachsener
A8: 16096 | B8: 109358 | C8: Herr | D8: Kurt | E8: Bauer | F8: Kurt Bauer | G8: Würzburger BV 1992 e.V. | H8: SW 77 Würzburg | I8: X | J8: Senioren C | K8: Erwachsener
A9: 7886 | B9: 112186 | C9: Herr | D9: Patrick | E9: Baszler | F9: Patrick Baszler | G9: Münchner Keglerverein e. V. | H9: BK München | I9: X | J9: Männer | K9: Erwachsener
A10: 38774 | B10: 158005 | C10: Herr | D10: Marcel | E10: Bassler | F10: Marcel Bassler | G10: BSC Lauf e.V. | H10: Team Räumkommando Lauf | I10: X | J10: Männer | K10: Erwachsener
A11: 25692 | B11: 87303 | C11: Herr | D11: Phuoc | E11: Barwig-Luu | F11: Phuoc Barwig-Luu | G11: BSC Lauf e.V. | H11: Team Räumkommando Lauf | I11: X | J11: Senioren A | K11: Erwachsener
A12: 16085 | B12: 112598 | C12: Herr | D12: Dieter | E12: Barthelmes | F12: Dieter Barthelmes | G12: 1. FC 45 Geldersheim | H12: Strikers Geldersheim 1983 | I12: X | J12: Senioren A | K12: Erwachsener
A13: 7907 | B13: 112054 | C13: Herr | D13: Theo | E13: Barthel | F13: Theo Barthel | G13: BV Schweinfurt 1974 e.V. | H13: BSC Schweinfurt-Ettleben | I13: X | J13: Senioren B | K13: Erwachsener
A14: 25344 | B14: 52752 | C14: Frau | D14: Manuela | E14: Balog | F14: Manuela Balog | G14: Münchner Keglerverein e. V. | H14: BC Bajuwaren | I14: X | J14: Frauen | K14: Erwachsener
A15: 25786 | B15: 99322 | C15: Herr | D15: Rene | E15: Baldauf | F15: Rene Baldauf | G15: Münchner Keglerverein e. V. | H15: 1. BSC Active Bowler Brunnthal | I15: X | J15: Männer | K15: Erwachsener
A16: 38837 | B16: 159623 | C16: Frau | D16: Argyro | E16: Bakogianni | F16: Argyro Bakogianni | G16: Münchner Keglerverein e. V. | H16: 1. BSC Active Bowler Brunnthal | I16: X | J16: Seniorinnen B | K16: Erwachsener
... A1052: 7330 | B1052: 111176 | C1052: Herr | D1052: Fritz | E1052: Wittmann | F1052: Fritz Wittmann | G1052: 1. BV 1984 Pfaffenhofen e.V. | H1052: BSC Pfaffenhofen | I1052: X | J1052: Senioren C | K1052: Erwachsener
A1055: 38934 | C1055: Frau | D1055: Denise | E1055: Schwertfeger | F1055: Denise Schwertfeger | G1055: Rottendorfer BV 1984 e.V. | H1055: SG-Rottendorf
A1056: 46018 | C1056: Herr | D1056: Axland | E1056: Magnus | F1056: Magnus Axland | G1056: Münchner Keglerverein e. V. | H1056: Einzelmitglied
A1057: 38314 | C1057: Herr | D1057: Markus | E1057: Hanauer | F1057: Markus Hanauer | G1057: 1. BC Bad Tölz 78 e.V. | H1057: Absolut Sports.com

Sheet Spieler
E1: Senioren A
G3: geworfene Pins | L3: HILOW | O3: Anzahl Spiele | T3: Schnitt | Y3: Teamplatzierung Berechnung | AE3: Schnittplatzierung Berechnung
G4: SP 1 | K4: Team | L4: Hilow 1 | M4: Hilow 2 | N4: Hilow 3 | O4: SP 1 | P4: Sp 2 | Q4: Sp 3 | R4: Sp 4 | S4: Team | T4: Sp 1 | U4: Sp 2 | V4: Sp 3 | W4: Sp 4 | X4: Team | Y4: Teamnr. | Z4: Sonderrechnung | AB4: Platz: | AC4: Sortierung Groß nach Klein | AD4: TeamNr. Platzierung | AE4: TeamNr | AG4: Platz | AH4: Sortierung Groß n. Klein | AI4: TeamNr.
A5: Teamnr. | B5: Spieler 1 | C5: Name Spieler 1 | D5: Name Spieler 3 | E5: Name Spieler 4
A6: 1 | B6: 7709 | C6: =IF(B6="","",VLOOKUP(B6,'Mitglieder BBU'!A:N,6,0)) -> Else Schuster | D6: =IF(#REF!="","",VLOOKUP(#REF!,'Mitglieder BBU'!A:N,6,0)) -> #REF! | E6: =IF(#REF!="","",VLOOKUP(#REF!,'Mitglieder BBU'!A:N,6,0)) -> #REF! | G6: =IFNA(VLOOKUP(B6,Datensammler!$B:$AA,24,0),"") -> 1858 | K6: =SUM(G6:J6) -> 1858 | L6: =IFERROR('HI-LOW Berechnung'!AS5,0) -> 68 | M6: =IFERROR('HI-LOW Berechnung'!AY5,0) -> 60 | N6: =IFERROR('HI-LOW Berechnung'!BB5,0) -> 43 | O6: =IFNA(VLOOKUP(B6,Datensammler!$B:$AA,25,0),"") -> 12 | S6: =SUM(O6:R6) -> 12 | T6: =IF(G6=0,"",G6/O6) -> 154.83333 | U6: =IF(H6=0,"",H6/P6) | V6: =IF(I6="","",I6/Q6) | W6: =IF(J6="","",J6/R6) | X6: =IF(K6=0,"",K6/S6) -> 154.83333 | Y6: 1 | Z6: =IF(K6=0,0,(900-L6)/100000+(900-M6)/100000000+(900-N6)/100000000000+Y6/100000000000) -> 0.0083284086 | AA6: =K6+Z6 -> 1858.0083 | AB6: 1 | AC6: =IFERROR(LARGE(AA:AA,Y6),"") -> 2441.0084 | AD6: =IF(AC6<>0,VLOOKUP(AC6,AA:AB,2,0),"") -> 9 | AE6: 1 | AF6: =IF(X6="","",ROUND(X6,3)+AE6/100000) -> 154.83301 | AG6: 1 | AH6: =IFERROR(LARGE(AF:AF,Y6),"") -> 203.41709 | AI6: =IF(AH6="","",VLOOKUP(AH6,AF:AG,2,0)) -> 9
A7: 2 | B7: 25347 | C7: =IF(B7="","",VLOOKUP(B7,'Mitglieder BBU'!A:N,6,0)) -> Roswitha Schulz-Burkert | D7: =IF(#REF!="","",VLOOKUP(#REF!,'Mitglieder BBU'!A:N,6,0)) -> #REF! | E7: =IF(#REF!="","",VLOOKUP(#REF!,'Mitglieder BBU'!A:N,6,0)) -> #REF! | G7: =IFNA(VLOOKUP(B7,Datensammler!$B:$AA,24,0),"") -> 1650 | K7: =SUM(G7:J7) -> 1650 | L7: =IFERROR('HI-LOW Berechnung'!AS6,0) -> 47 | M7: =IFERROR('HI-LOW Berechnung'!AY6,0) -> 33 | N7: =IFERROR('HI-LOW Berechnung'!BB6,0) -> 30 | O7: =IFNA(VLOOKUP(B7,Datensammler!$B:$AA,25,0),"") -> 12 | S7: =SUM(O7:R7) -> 12 | T7: =IF(G7=0,"",G7/O7) -> 137.5 | U7: =IF(H7=0,"",H7/P7) | V7: =IF(I7="","",I7/Q7) | W7: =IF(J7="","",J7/R7) | X7: =IF(K7=0,"",K7/S7) -> 137.5 | Y7: 2 | Z7: =IF(K7=0,0,(900-L7)/100000+(900-M7)/100000000+(900-N7)/100000000000+Y7/100000000000) -> 0.0085386787 | AA7: =K7+Z7 -> 1650.0085 | AB7: 2 | AC7: =IFERROR(LARGE(AA:AA,Y7),"") -> 2346.0081 | AD7: =IF(AC7<>0,VLOOKUP(AC7,AA:AB,2,0),"") -> 14 | AE7: 2 | AF7: =IF(X7="","",ROUND(X7,3)+AE7/100000) -> 137.50002 | AG7: 2 | AH7: =IFERROR(LARGE(AF:AF,Y7),"") -> 195.50014 | AI7: =IF(AH7="","",VLOOKUP(AH7,AF:AG,2,0)) -> 14
A8: 3 | B8: 7974 | C8: =IF(B8="","",VLOOKUP(B8,'Mitglieder BBU'!A:N,6,0)) -> Ingeborg Schmitt | D8: =IF(#REF!="","",VLOOKUP(#REF!,'Mitglieder BBU'!A:N,6,0)) -> #REF! | E8: =IF(#REF!="","",VLOOKUP(#REF!,'Mitglieder BBU'!A:N,6,0)) -> #REF! | G8: =IFNA(VLOOKUP(B8,Datensammler!$B:$AA,24,0),"") -> 1596 | K8: =SUM(G8:J8) -> 1596 | L8: =IFERROR('HI-LOW Berechnung'!AS7,0) -> 61 | M8: =IFERROR('HI-LOW Berechnung'!AY7,0) -> 43 | N8: =IFERROR('HI-LOW Berechnung'!BB7,0) -> 32 | O8: =IFNA(VLOOKUP(B8,Datensammler!$B:$AA,25,0),"") -> 12 | S8: =SUM(O8:R8) -> 12 | T8: =IF(G8=0,"",G8/O8) -> 133 | U8: =IF(H8=0,"",H8/P8) | V8: =IF(I8="","",I8/Q8) | W8: =IF(J8="","",J8/R8) | X8: =IF(K8=0,"",K8/S8) -> 133 | Y8: 3 | Z8: =IF(K8=0,0,(900-L8)/100000+(900-M8)/100000000+(900-N8)/100000000000+Y8/100000000000) -> 0.0083985787 | AA8: =K8+Z8 -> 1596.0084 | AB8: 3 | AC8: =IFERROR(LARGE(AA:AA,Y8),"") -> 2269.0079 | AD8: =IF(AC8<>0,VLOOKUP(AC8,AA:AB,2,0),"") -> 15 | AE8: 3 | AF8: =IF(X8="","",ROUND(X8,3)+AE8/100000) -> 133.00003 | AG8: 3 | AH8: =IFERROR(LARGE(AF:AF,Y8),"") -> 189.08315 | AI8: =IF(AH8="","",VLOOKUP(AH8,AF:AG,2,0)) -> 15
A9: 4 | B9: 25329 | C9: =IF(B9="","",VLOOKUP(B9,'Mitglieder BBU'!A:N,6,0)) -> Katharina Mang | D9: =IF(#REF!="","",VLOOKUP(#REF!,'Mitglieder BBU'!A:N,6,0)) -> #REF! | E9: =IF(#REF!="","",VLOOKUP(#REF!,'Mitglieder BBU'!A:N,6,0)) -> #REF! | G9: =IFNA(VLOOKUP(B9,Datensammler!$B:$AA,24,0),"") -> 1983 | K9: =SUM(G9:J9) -> 1983 | L9: =IFERROR('HI-LOW Berechnung'!AS8,0) -> 67 | M9: =IFERROR('HI-LOW Berechnung'!AY8,0) -> 37 | N9: =IFERROR('HI-LOW Berechnung'!BB8,0) -> 34 | O9: =IFNA(VLOOKUP(B9,Datensammler!$B:$AA,25,0),"") -> 12 | S9: =SUM(O9:R9) -> 12 | T9: =IF(G9=0,"",G9/O9) -> 165.25 | U9: =IF(H9=0,"",H9/P9) | V9: =IF(I9="","",I9/Q9) | W9: =IF(J9="","",J9/R9) | X9: =IF(K9=0,"",K9/S9) -> 165.25 | Y9: 4 | Z9: =IF(K9=0,0,(900-L9)/100000+(900-M9)/100000000+(900-N9)/100000000000+Y9/100000000000) -> 0.0083386387 | AA9: =K9+Z9 -> 1983.0083 | AB9: 4 | AC9: =IFERROR(LARGE(AA:AA,Y9),"") -> 2200.008 | AD9: =IF(AC9<>0,VLOOKUP(AC9,AA:AB,2,0),"") -> 18 | AE9: 4 | AF9: =IF(X9="","",ROUND(X9,3)+AE9/100000) -> 165.25004 | AG9: 4 | AH9: =IFERROR(LARGE(AF:AF,Y9),"") -> 183.33318 | AI9: =IF(AH9="","",VLOOKUP(AH9,AF:AG,2,0)) -> 18
A10: 5 | B10: 38934 | C10: =IF(B10="","",VLOOKUP(B10,'Mitglieder BBU'!A:N,6,0)) -> Denise Schwertfeger | D10: =IF(#REF!="","",VLOOKUP(#REF!,'Mitglieder BBU'!A:N,6,0)) -> #REF! | E10: =IF(#REF!="","",VLOOKUP(#REF!,'Mitglieder BBU'!A:N,6,0)) -> #REF! | G10: =IFNA(VLOOKUP(B10,Datensammler!$B:$AA,24,0),"") -> 1701 | K10: =SUM(G10:J10) -> 1701 | L10: =IFERROR('HI-LOW Berechnung'!AS9,0) -> 71 | M10: =IFERROR('HI-LOW Berechnung'!AY9,0) -> 37 | N10: =IFERROR('HI-LOW Berechnung'!BB9,0) -> 28 | O10: =IFNA(VLOOKUP(B10,Datensammler!$B:$AA,25,0),"") -> 12 | S10: =SUM(O10:R10) -> 12 | T10: =IF(G10=0,"",G10/O10) -> 141.75 | U10: =IF(H10=0,"",H10/P10) | V10: =IF(I10="","",I10/Q10) | W10: =IF(J10="","",J10/R10) | X10: =IF(K10=0,"",K10/S10) -> 141.75 | Y10: 5 | Z10: =IF(K10=0,0,(900-L10)/100000+(900-M10)/100000000+(900-N10)/100000000000+Y10/100000000000) -> 0.0082986388 | AA10: =K10+Z10 -> 1701.0083 | AB10: 5 | AC10: =IFERROR(LARGE(AA:AA,Y10),"") -> 2157.0085 | AD10: =IF(AC10<>0,VLOOKUP(AC10,AA:AB,2,0),"") -> 20 | AE10: 5 | AF10: =IF(X10="","",ROUND(X10,3)+AE10/100000) -> 141.75005 | AG10: 5 | AH10: =IFERROR(LARGE(AF:AF,Y10),"") -> 179.7502 | AI10: =IF(AH10="","",VLOOKUP(AH10,AF:AG,2,0)) -> 20
A11: 6 | B11: 16595 | C11: =IF(B11="","",VLOOKUP(B11,'Mitglieder BBU'!A:N,6,0)) -> Nicole Schott | D11: =IF(#REF!="","",VLOOKUP(#REF!,'Mitglieder BBU'!A:N,6,0)) -> #REF! | E11: =IF(#REF!="","",VLOOKUP(#REF!,'Mitglieder BBU'!A:N,6,0)) -> #REF! | G11: =IFNA(VLOOKUP(B11,Datensammler!$B:$AA,24,0),"") -> 1997 | K11: =SUM(G11:J11) -> 1997 | L11: =IFERROR('HI-LOW Berechnung'!AS10,0) -> 60 | M11: =IFERROR('HI-LOW Berechnung'!AY10,0) -> 53 | N11: =IFERROR('HI-LOW Berechnung'!BB10,0) -> 39 | O11: =IFNA(VLOOKUP(B11,Datensammler!$B:$AA,25,0),"") -> 12 | S11: =SUM(O11:R11) -> 12 | T11: =IF(G11=0,"",G11/O11) -> 166.41667 | U11: =IF(H11=0,"",H11/P11) | V11: =IF(I11="","",I11/Q11) | W11: =IF(J11="","",J11/R11) | X11: =IF(K11=0,"",K11/S11) -> 166.41667 | Y11: 6 | Z11: =IF(K11=0,0,(900-L11)/100000+(900-M11)/100000000+(900-N11)/100000000000+Y11/100000000000) -> 0.0084084787 | AA11: =K11+Z11 -> 1997.0084 | AB11: 6 | AC11: =IFERROR(LARGE(AA:AA,Y11),"") -> 2081.0085 | AD11: =IF(AC11<>0,VLOOKUP(AC11,AA:AB,2,0),"") -> 19 | AE11: 6 | AF11: =IF(X11="","",ROUND(X11,3)+AE11/100000) -> 166.41706 | AG11: 6 | AH11: =IFERROR(LARGE(AF:AF,Y11),"") -> 173.41719 | AI11: =IF(AH11="","",VLOOKUP(AH11,AF:AG,2,0)) -> 19
A12: 7 | B12: 16594 | C12: =IF(B12="","",VLOOKUP(B12,'Mitglieder BBU'!A:N,6,0)) -> Monika Schott | D12: =IF(#REF!="","",VLOOKUP(#REF!,'Mitglieder BBU'!A:N,6,0)) -> #REF! | E12: =IF(#REF!="","",VLOOKUP(#REF!,'Mitglieder BBU'!A:N,6,0)) -> #REF! | G12: =IFNA(VLOOKUP(B12,Datensammler!$B:$AA,24,0),"") -> 1959 | K12: =SUM(G12:J12) -> 1959 | L12: =IFERROR('HI-LOW Berechnung'!AS11,0) -> 56 | M12: =IFERROR('HI-LOW Berechnung'!AY11,0) -> 33 | N12: =IFERROR('HI-LOW Berechnung'!BB11,0) -> 20 | O12: =IFNA(VLOOKUP(B12,Datensammler!$B:$AA,25,0),"") -> 12 | S12: =SUM(O12:R12) -> 12 | T12: =IF(G12=0,"",G12/O12) -> 163.25 | U12: =IF(H12=0,"",H12/P12) | V12: =IF(I12="","",I12/Q12) | W12: =IF(J12="","",J12/R12) | X12: =IF(K12=0,"",K12/S12) -> 163.25 | Y12: 7 | Z12: =IF(K12=0,0,(900-L12)/100000+(900-M12)/100000000+(900-N12)/100000000000+Y12/100000000000) -> 0.0084486789 | AA12: =K12+Z12 -> 1959.0084 | AB12: 7 | AC12: =IFERROR(LARGE(AA:AA,Y12),"") -> 2079.0083 | AD12: =IF(AC12<>0,VLOOKUP(AC12,AA:AB,2,0),"") -> 22 | AE12: 7 | AF12: =IF(X12="","",ROUND(X12,3)+AE12/100000) -> 163.25007 | AG12: 7 | AH12: =IFERROR(LARGE(AF:AF,Y12),"") -> 173.25022 | AI12: =IF(AH12="","",VLOOKUP(AH12,AF:AG,2,0)) -> 22
A13: 8 | B13: 38931 | C13: =IF(B13="","",VLOOKUP(B13,'Mitglieder BBU'!A:N,6,0)) -> Helene Schick | D13: =IF(#REF!="","",VLOOKUP(#REF!,'Mitglieder BBU'!A:N,6,0)) -> #REF! | E13: =IF(#REF!="","",VLOOKUP(#REF!,'Mitglieder BBU'!A:N,6,0)) -> #REF! | G13: =IFNA(VLOOKUP(B13,Datensammler!$B:$AA,24,0),"") -> 1955 | K13: =SUM(G13:J13) -> 1955 | L13: =IFERROR('HI-LOW Berechnung'!AS12,0) -> 61 | M13: =IFERROR('HI-LOW Berechnung'!AY12,0) -> 45 | N13: =IFERROR('HI-LOW Berechnung'!BB12,0) -> 43 | O13: =IFNA(VLOOKUP(B13,Datensammler!$B:$AA,25,0),"") -> 12 | S13: =SUM(O13:R13) -> 12 | T13: =IF(G13=0,"",G13/O13) -> 162.91667 | U13: =IF(H13=0,"",H13/P13) | V13: =IF(I13="","",I13/Q13) | W13: =IF(J13="","",J13/R13) | X13: =IF(K13=0,"",K13/S13) -> 162.91667 | Y13: 8 | Z13: =IF(K13=0,0,(900-L13)/100000+(900-M13)/100000000+(900-N13)/100000000000+Y13/100000000000) -> 0.0083985587 | AA13: =K13+Z13 -> 1955.0084 | AB13: 8 | AC13: =IFERROR(LARGE(AA:AA,Y13),"") -> 2037.0083 | AD13: =IF(AC13<>0,VLOOKUP(AC13,AA:AB,2,0),"") -> 17 | AE13: 8 | AF13: =IF(X13="","",ROUND(X13,3)+AE13/100000) -> 162.91708 | AG13: 8 | AH13: =IFERROR(LARGE(AF:AF,Y13),"") -> 169.75017 | AI13: =IF(AH13="","",VLOOKUP(AH13,AF:AG,2,0)) -> 17
A14: 9 | B14: 38045 | C14: =IF(B14="","",VLOOKUP(B14,'Mitglieder BBU'!A:N,6,0)) -> Anika Kristof | D14: =IF(#REF!="","",VLOOKUP(#REF!,'Mitglieder BBU'!A:N,6,0)) -> #REF! | E14: =IF(#REF!="","",VLOOKUP(#REF!,'Mitglieder BBU'!A:N,6,0)) -> #REF! | G14: =IFNA(VLOOKUP(B14,Datensammler!$B:$AA,24,0),"") -> 2441 | K14: =SUM(G14:J14) -> 2441 | L14: =IFERROR('HI-LOW Berechnung'!AS13,0) -> 64 | M14: =IFERROR('HI-LOW Berechnung'!AY13,0) -> 42 | N14: =IFERROR('HI-LOW Berechnung'!BB13,0) -> 28 | O14: =IFNA(VLOOKUP(B14,Datensammler!$B:$AA,25,0),"") -> 12 | S14: =SUM(O14:R14) -> 12 | T14: =IF(G14=0,"",G14/O14) -> 203.41667 | U14: =IF(H14=0,"",H14/P14) | V14: =IF(I14="","",I14/Q14) | W14: =IF(J14="","",J14/R14) | X14: =IF(K14=0,"",K14/S14) -> 203.41667 | Y14: 9 | Z14: =IF(K14=0,0,(900-L14)/100000+(900-M14)/100000000+(900-N14)/100000000000+Y14/100000000000) -> 0.0083685888 | AA14: =K14+Z14 -> 2441.0084 | AB14: 9 | AC14: =IFERROR(LARGE(AA:AA,Y14),"") -> 1997.0084 | AD14: =IF(AC14<>0,VLOOKUP(AC14,AA:AB,2,0),"") -> 6 | AE14: 9 | AF14: =IF(X14="","",ROUND(X14,3)+AE14/100000) -> 203.41709 | AG14: 9 | AH14: =IFERROR(LARGE(AF:AF,Y14),"") -> 166.41706 | AI14: =IF(AH14="","",VLOOKUP(AH14,AF:AG,2,0)) -> 6
A15: 10 | B15: 38876 | C15: =IF(B15="","",VLOOKUP(B15,'Mitglieder BBU'!A:N,6,0)) -> Bianca Leinemann | D15: =IF(#REF!="","",VLOOKUP(#REF!,'Mitglieder BBU'!A:N,6,0)) -> #REF! | E15: =IF(#REF!="","",VLOOKUP(#REF!,'Mitglieder BBU'!A:N,6,0)) -> #REF! | G15: =IFNA(VLOOKUP(B15,Datensammler!$B:$AA,24,0),"") -> 1823 | K15: =SUM(G15:J15) -> 1823 | L15: =IFERROR('HI-LOW Berechnung'!AS14,0) -> 95 | M15: =IFERROR('HI-LOW Berechnung'!AY14,0) -> 50 | N15: =IFERROR('HI-LOW Berechnung'!BB14,0) -> 19 | O15: =IFNA(VLOOKUP(B15,Datensammler!$B:$AA,25,0),"") -> 12 | S15: =SUM(O15:R15) -> 12 | T15: =IF(G15=0,"",G15/O15) -> 151.91667 | U15: =IF(H15=0,"",H15/P15) | V15: =IF(I15="","",I15/Q15) | W15: =IF(J15="","",J15/R15) | X15: =IF(K15=0,"",K15/S15) -> 151.91667 | Y15: 10 | Z15: =IF(K15=0,0,(900-L15)/100000+(900-M15)/100000000+(900-N15)/100000000000+Y15/100000000000) -> 0.0080585089 | AA15: =K15+Z15 -> 1823.0081 | AB15: 10 | AC15: =IFERROR(LARGE(AA:AA,Y15),"") -> 1983.0083 | AD15: =IF(AC15<>0,VLOOKUP(AC15,AA:AB,2,0),"") -> 4 | AE15: 10 | AF15: =IF(X15="","",ROUND(X15,3)+AE15/100000) -> 151.9171 | AG15: 10 | AH15: =IFERROR(LARGE(AF:AF,Y15),"") -> 165.25004 | AI15: =IF(AH15="","",VLOOKUP(AH15,AF:AG,2,0)) -> 4
A16: 11 | B16: 38780 | C16: =IF(B16="","",VLOOKUP(B16,'Mitglieder BBU'!A:N,6,0)) -> Sabaithip Mekjinda | D16: =IF(#REF!="","",VLOOKUP(#REF!,'Mitglieder BBU'!A:N,6,0)) -> #REF! | E16: =IF(#REF!="","",VLOOKUP(#REF!,'Mitglieder BBU'!A:N,6,0)) -> #REF! | G16: =IFNA(VLOOKUP(B16,Datensammler!$B:$AA,24,0),"") -> 1799 | K16: =SUM(G16:J16) -> 1799 | L16: =IFERROR('HI-LOW Berechnung'!AS15,0) -> 48 | M16: =IFERROR('HI-LOW Berechnung'!AY15,0) -> 30 | N16: =IFERROR('HI-LOW Berechnung'!BB15,0) -> 27 | O16: =IFNA(VLOOKUP(B16,Datensammler!$B:$AA,25,0),"") -> 12 | S16: =SUM(O16:R16) -> 12 | T16: =IF(G16=0,"",G16/O16) -> 149.91667 | U16: =IF(H16=0,"",H16/P16) | V16: =IF(I16="","",I16/Q16) | W16: =IF(J16="","",J16/R16) | X16: =IF(K16=0,"",K16/S16) -> 149.91667 | Y16: 11 | Z16: =IF(K16=0,0,(900-L16)/100000+(900-M16)/100000000+(900-N16)/100000000000+Y16/100000000000) -> 0.0085287088 | AA16: =K16+Z16 -> 1799.0085 | AB16: 11 | AC16: =IFERROR(LARGE(AA:AA,Y16),"") -> 1959.0084 | AD16: =IF(AC16<>0,VLOOKUP(AC16,AA:AB,2,0),"") -> 7 | AE16: 11 | AF16: =IF(X16="","",ROUND(X16,3)+AE16/100000) -> 149.91711 | AG16: 11 | AH16: =IFERROR(LARGE(AF:AF,Y16),"") -> 163.25007 | AI16: =IF(AH16="","",VLOOKUP(AH16,AF:AG,2,0)) -> 7
A17: 12 | B17: 38789 | C17: =IF(B17="","",VLOOKUP(B17,'Mitglieder BBU'!A:N,6,0)) -> Stephanie Fischer | D17: =IF(#REF!="","",VLOOKUP(#REF!,'Mitglieder BBU'!A:N,6,0)) -> #REF! | E17: =IF(#REF!="","",VLOOKUP(#REF!,'Mitglieder BBU'!A:N,6,0)) -> #REF! | G17: =IFNA(VLOOKUP(B17,Datensammler!$B:$AA,24,0),"") -> 1574 | K17: =SUM(G17:J17) -> 1574 | L17: =IFERROR('HI-LOW Berechnung'!AS16,0) -> 70 | M17: =IFERROR('HI-LOW Berechnung'!AY16,0) -> 46 | N17: =IFERROR('HI-LOW Berechnung'!BB16,0) -> 26 | O17: =IFNA(VLOOKUP(B17,Datensammler!$B:$AA,25,0),"") -> 12 | S17: =SUM(O17:R17) -> 12 | T17: =IF(G17=0,"",G17/O17) -> 131.16667 | U17: =IF(H17=0,"",H17/P17) | V17: =IF(I17="","",I17/Q17) | W17: =IF(J17="","",J17/R17) | X17: =IF(K17=0,"",K17/S17) -> 131.16667 | Y17: 12 | Z17: =IF(K17=0,0,(900-L17)/100000+(900-M17)/100000000+(900-N17)/100000000000+Y17/100000000000) -> 0.0083085489 | AA17: =K17+Z17 -> 1574.0083 | AB17: 12 | AC17: =IFERROR(LARGE(AA:AA,Y17),"") -> 1955.0084 | AD17: =IF(AC17<>0,VLOOKUP(AC17,AA:AB,2,0),"") -> 8 | AE17: 12 | AF17: =IF(X17="","",ROUND(X17,3)+AE17/100000) -> 131.16712 | AG17: 12 | AH17: =IFERROR(LARGE(AF:AF,Y17),"") -> 162.91708 | AI17: =IF(AH17="","",VLOOKUP(AH17,AF:AG,2,0)) -> 8
... A27: 22 | B27: 7154 | C27: =IF(B27="","",VLOOKUP(B27,'Mitglieder BBU'!A:N,6,0)) -> Marina Weiske | D27: =IF(#REF!="","",VLOOKUP(#REF!,'Mitglieder BBU'!A:N,6,0)) -> #REF! | E27: =IF(#REF!="","",VLOOKUP(#REF!,'Mitglieder BBU'!A:N,6,0)) -> #REF! | G27: =IFNA(VLOOKUP(B27,Datensammler!$B:$AA,24,0),"") -> 2079 | K27: =SUM(G27:J27) -> 2079 | L27: =IFERROR('HI-LOW Berechnung'!AS26,0) -> 68 | M27: =IFERROR('HI-LOW Berechnung'!AY26,0) -> 43 | N27: =IFERROR('HI-LOW Berechnung'!BB26,0) -> 31 | O27: =IFNA(VLOOKUP(B27,Datensammler!$B:$AA,25,0),"") -> 12 | S27: =SUM(O27:R27) -> 12 | T27: =IF(G27=0,"",G27/O27) -> 173.25 | U27: =IF(H27=0,"",H27/P27) | V27: =IF(I27="","",I27/Q27) | W27: =IF(J27="","",J27/R27) | X27: =IF(K27=0,"",K27/S27) -> 173.25 | Y27: 22 | Z27: =IF(K27=0,0,(900-L27)/100000+(900-M27)/100000000+(900-N27)/100000000000+Y27/100000000000) -> 0.0083285789 | AA27: =K27+Z27 -> 2079.0083 | AB27: 22 | AC27: =IFERROR(LARGE(AA:AA,Y27),"") -> 1574.0083 | AD27: =IF(AC27<>0,VLOOKUP(AC27,AA:AB,2,0),"") -> 12 | AE27: 22 | AF27: =IF(X27="","",ROUND(X27,3)+AE27/100000) -> 173.25022 | AG27: 22 | AH27: =IFERROR(LARGE(AF:AF,Y27),"") -> 131.16712 | AI27: =IF(AH27="","",VLOOKUP(AH27,AF:AG,2,0)) -> 12
A28: 23 | C28: =IF(B28="","",VLOOKUP(B28,'Mitglieder BBU'!A:N,6,0)) | D28: =IF(#REF!="","",VLOOKUP(#REF!,'Mitglieder BBU'!A:N,6,0)) -> #REF! | E28: =IF(#REF!="","",VLOOKUP(#REF!,'Mitglieder BBU'!A:N,6,0)) -> #REF! | G28: =IFNA(VLOOKUP(B28,Datensammler!$B:$AA,24,0),"") | K28: =SUM(G28:J28) -> 0 | L28: =IFERROR('HI-LOW Berechnung'!AS27,0) -> 0 | M28: =IFERROR('HI-LOW Berechnung'!AY27,0) -> 0 | N28: =IFERROR('HI-LOW Berechnung'!BB27,0) -> 0 | O28: =IFNA(VLOOKUP(B28,Datensammler!$B:$AA,25,0),"") | S28: =SUM(O28:R28) -> 0 | T28: =IF(G28=0,"",G28/O28) -> #DIV/0! | U28: =IF(H28=0,"",H28/P28) | V28: =IF(I28="","",I28/Q28) | W28: =IF(J28="","",J28/R28) | X28: =IF(K28=0,"",K28/S28) | Y28: 23 | Z28: =IF(K28=0,0,(900-L28)/100000+(900-M28)/100000000+(900-N28)/100000000000+Y28/100000000000) -> 0 | AA28: =K28+Z28 -> 0 | AB28: 23 | AC28: =IFERROR(LARGE(AA:AA,Y28),"") -> 0 | AD28: =IF(AC28<>0,VLOOKUP(AC28,AA:AB,2,0),"") | AE28: 23 | AF28: =IF(X28="","",ROUND(X28,3)+AE28/100000) | AG28: 23 | AH28: =IFERROR(LARGE(AF:AF,Y28),"") | AI28: =IF(AH28="","",VLOOKUP(AH28,AF:AG,2,0))
A29: 24 | C29: =IF(B29="","",VLOOKUP(B29,'Mitglieder BBU'!A:N,6,0)) | D29: =IF(#REF!="","",VLOOKUP(#REF!,'Mitglieder BBU'!A:N,6,0)) -> #REF! | E29: =IF(#REF!="","",VLOOKUP(#REF!,'Mitglieder BBU'!A:N,6,0)) -> #REF! | G29: =IFNA(VLOOKUP(B29,Datensammler!$B:$AA,24,0),"") | K29: =SUM(G29:J29) -> 0 | L29: =IFERROR('HI-LOW Berechnung'!AS28,0) -> 0 | M29: =IFERROR('HI-LOW Berechnung'!AY28,0) -> 0 | N29: =IFERROR('HI-LOW Berechnung'!BB28,0) -> 0 | O29: =IFNA(VLOOKUP(B29,Datensammler!$B:$AA,25,0),"") | S29: =SUM(O29:R29) -> 0 | T29: =IF(G29=0,"",G29/O29) -> #DIV/0! | U29: =IF(H29=0,"",H29/P29) | V29: =IF(I29="","",I29/Q29) | W29: =IF(J29="","",J29/R29) | X29: =IF(K29=0,"",K29/S29) | Y29: 24 | Z29: =IF(K29=0,0,(900-L29)/100000+(900-M29)/100000000+(900-N29)/100000000000+Y29/100000000000) -> 0 | AA29: =K29+Z29 -> 0 | AB29: 24 | AC29: =IFERROR(LARGE(AA:AA,Y29),"") -> 0 | AD29: =IF(AC29<>0,VLOOKUP(AC29,AA:AB,2,0),"") | AE29: 24 | AF29: =IF(X29="","",ROUND(X29,3)+AE29/100000) | AG29: 24 | AH29: =IFERROR(LARGE(AF:AF,Y29),"") | AI29: =IF(AH29="","",VLOOKUP(AH29,AF:AG,2,0))
A30: 25 | C30: =IF(B30="","",VLOOKUP(B30,'Mitglieder BBU'!A:N,6,0)) | D30: =IF(#REF!="","",VLOOKUP(#REF!,'Mitglieder BBU'!A:N,6,0)) -> #REF! | E30: =IF(#REF!="","",VLOOKUP(#REF!,'Mitglieder BBU'!A:N,6,0)) -> #REF! | G30: =IFNA(VLOOKUP(B30,Datensammler!$B:$AA,24,0),"") | K30: =SUM(G30:J30) -> 0 | L30: =IFERROR('HI-LOW Berechnung'!AS29,0) -> 0 | M30: =IFERROR('HI-LOW Berechnung'!AY29,0) -> 0 | N30: =IFERROR('HI-LOW Berechnung'!BB29,0) -> 0 | O30: =IFNA(VLOOKUP(B30,Datensammler!$B:$AA,25,0),"") | S30: =SUM(O30:R30) -> 0 | T30: =IF(G30=0,"",G30/O30) -> #DIV/0! | U30: =IF(H30=0,"",H30/P30) | V30: =IF(I30="","",I30/Q30) | W30: =IF(J30="","",J30/R30) | X30: =IF(K30=0,"",K30/S30) | Y30: 25 | Z30: =IF(K30=0,0,(900-L30)/100000+(900-M30)/100000000+(900-N30)/100000000000+Y30/100000000000) -> 0 | AA30: =K30+Z30 -> 0 | AB30: 25 | AC30: =IFERROR(LARGE(AA:AA,Y30),"") -> 0 | AD30: =IF(AC30<>0,VLOOKUP(AC30,AA:AB,2,0),"") | AE30: 25 | AF30: =IF(X30="","",ROUND(X30,3)+AE30/100000) | AG30: 25 | AH30: =IFERROR(LARGE(AF:AF,Y30),"") | AI30: =IF(AH30="","",VLOOKUP(AH30,AF:AG,2,0))
A31: 26 | C31: =IF(B31="","",VLOOKUP(B31,'Mitglieder BBU'!A:N,6,0)) | D31: =IF(#REF!="","",VLOOKUP(#REF!,'Mitglieder BBU'!A:N,6,0)) -> #REF! | E31: =IF(#REF!="","",VLOOKUP(#REF!,'Mitglieder BBU'!A:N,6,0)) -> #REF! | G31: =IFNA(VLOOKUP(B31,Datensammler!$B:$AA,24,0),"") | K31: =SUM(G31:J31) -> 0 | L31: =IFERROR('HI-LOW Berechnung'!AS30,0) -> 0 | M31: =IFERROR('HI-LOW Berechnung'!AY30,0) -> 0 | N31: =IFERROR('HI-LOW Berechnung'!BB30,0) -> 0 | O31: =IFNA(VLOOKUP(B31,Datensammler!$B:$AA,25,0),"") | S31: =SUM(O31:R31) -> 0 | T31: =IF(G31=0,"",G31/O31) -> #DIV/0! | U31: =IF(H31=0,"",H31/P31) | V31: =IF(I31="","",I31/Q31) | W31: =IF(J31="","",J31/R31) | X31: =IF(K31=0,"",K31/S31) | Y31: 26 | Z31: =IF(K31=0,0,(900-L31)/100000+(900-M31)/100000000+(900-N31)/100000000000+Y31/100000000000) -> 0 | AA31: =K31+Z31 -> 0 | AB31: 26 | AC31: =IFERROR(LARGE(AA:AA,Y31),"") -> 0 | AD31: =IF(AC31<>0,VLOOKUP(AC31,AA:AB,2,0),"") | AE31: 26 | AF31: =IF(X31="","",ROUND(X31,3)+AE31/100000) | AG31: 26 | AH31: =IFERROR(LARGE(AF:AF,Y31),"") | AI31: =IF(AH31="","",VLOOKUP(AH31,AF:AG,2,0))
A32: 27 | C32: =IF(B32="","",VLOOKUP(B32,'Mitglieder BBU'!A:N,6,0)) | D32: =IF(#REF!="","",VLOOKUP(#REF!,'Mitglieder BBU'!A:N,6,0)) -> #REF! | E32: =IF(#REF!="","",VLOOKUP(#REF!,'Mitglieder BBU'!A:N,6,0)) -> #REF! | G32: =IFNA(VLOOKUP(B32,Datensammler!$B:$AA,24,0),"") | K32: =SUM(G32:J32) -> 0 | L32: =IFERROR('HI-LOW Berechnung'!AS31,0) -> 0 | M32: =IFERROR('HI-LOW Berechnung'!AY31,0) -> 0 | N32: =IFERROR('HI-LOW Berechnung'!BB31,0) -> 0 | O32: =IFNA(VLOOKUP(B32,Datensammler!$B:$AA,25,0),"") | S32: =SUM(O32:R32) -> 0 | T32: =IF(G32=0,"",G32/O32) -> #DIV/0! | U32: =IF(H32=0,"",H32/P32) | V32: =IF(I32="","",I32/Q32) | W32: =IF(J32="","",J32/R32) | X32: =IF(K32=0,"",K32/S32) | Y32: 27 | Z32: =IF(K32=0,0,(900-L32)/100000+(900-M32)/100000000+(900-N32)/100000000000+Y32/100000000000) -> 0 | AA32: =K32+Z32 -> 0 | AB32: 27 | AC32: =IFERROR(LARGE(AA:AA,Y32),"") -> 0 | AD32: =IF(AC32<>0,VLOOKUP(AC32,AA:AB,2,0),"") | AE32: 27 | AF32: =IF(X32="","",ROUND(X32,3)+AE32/100000) | AG32: 27 | AH32: =IFERROR(LARGE(AF:AF,Y32),"") | AI32: =IF(AH32="","",VLOOKUP(AH32,AF:AG,2,0))
A33: 28 | C33: =IF(B33="","",VLOOKUP(B33,'Mitglieder BBU'!A:N,6,0)) | D33: =IF(#REF!="","",VLOOKUP(#REF!,'Mitglieder BBU'!A:N,6,0)) -> #REF! | E33: =IF(#REF!="","",VLOOKUP(#REF!,'Mitglieder BBU'!A:N,6,0)) -> #REF! | G33: =IFNA(VLOOKUP(B33,Datensammler!$B:$AA,24,0),"") | K33: =SUM(G33:J33) -> 0 | L33: =IFERROR('HI-LOW Berechnung'!AS32,0) -> 0 | M33: =IFERROR('HI-LOW Berechnung'!AY32,0) -> 0 | N33: =IFERROR('HI-LOW Berechnung'!BB32,0) -> 0 | O33: =IFNA(VLOOKUP(B33,Datensammler!$B:$AA,25,0),"") | S33: =SUM(O33:R33) -> 0 | T33: =IF(G33=0,"",G33/O33) -> #DIV/0! | U33: =IF(H33=0,"",H33/P33) | V33: =IF(I33="","",I33/Q33) | W33: =IF(J33="","",J33/R33) | X33: =IF(K33=0,"",K33/S33) | Y33: 28 | Z33: =IF(K33=0,0,(900-L33)/100000+(900-M33)/100000000+(900-N33)/100000000000+Y33/100000000000) -> 0 | AA33: =K33+Z33 -> 0 | AB33: 28 | AC33: =IFERROR(LARGE(AA:AA,Y33),"") -> 0 | AD33: =IF(AC33<>0,VLOOKUP(AC33,AA:AB,2,0),"") | AE33: 28 | AF33: =IF(X33="","",ROUND(X33,3)+AE33/100000) | AG33: 28 | AH33: =IFERROR(LARGE(AF:AF,Y33),"") | AI33: =IF(AH33="","",VLOOKUP(AH33,AF:AG,2,0))
A34: 29 | C34: =IF(B34="","",VLOOKUP(B34,'Mitglieder BBU'!A:N,6,0)) | D34: =IF(#REF!="","",VLOOKUP(#REF!,'Mitglieder BBU'!A:N,6,0)) -> #REF! | E34: =IF(#REF!="","",VLOOKUP(#REF!,'Mitglieder BBU'!A:N,6,0)) -> #REF! | G34: =IFNA(VLOOKUP(B34,Datensammler!$B:$AA,24,0),"") | K34: =SUM(G34:J34) -> 0 | L34: =IFERROR('HI-LOW Berechnung'!AS33,0) -> 0 | M34: =IFERROR('HI-LOW Berechnung'!AY33,0) -> 0 | N34: =IFERROR('HI-LOW Berechnung'!BB33,0) -> 0 | O34: =IFNA(VLOOKUP(B34,Datensammler!$B:$AA,25,0),"") | S34: =SUM(O34:R34) -> 0 | T34: =IF(G34=0,"",G34/O34) -> #DIV/0! | U34: =IF(H34=0,"",H34/P34) | V34: =IF(I34="","",I34/Q34) | W34: =IF(J34="","",J34/R34) | X34: =IF(K34=0,"",K34/S34) | Y34: 29 | Z34: =IF(K34=0,0,(900-L34)/100000+(900-M34)/100000000+(900-N34)/100000000000+Y34/100000000000) -> 0 | AA34: =K34+Z34 -> 0 | AB34: 29 | AC34: =IFERROR(LARGE(AA:AA,Y34),"") -> 0 | AD34: =IF(AC34<>0,VLOOKUP(AC34,AA:AB,2,0),"") | AE34: 29 | AF34: =IF(X34="","",ROUND(X34,3)+AE34/100000) | AG34: 29 | AH34: =IFERROR(LARGE(AF:AF,Y34),"") | AI34: =IF(AH34="","",VLOOKUP(AH34,AF:AG,2,0))
A35: 30 | C35: =IF(B35="","",VLOOKUP(B35,'Mitglieder BBU'!A:N,6,0)) | D35: =IF(#REF!="","",VLOOKUP(#REF!,'Mitglieder BBU'!A:N,6,0)) -> #REF! | E35: =IF(#REF!="","",VLOOKUP(#REF!,'Mitglieder BBU'!A:N,6,0)) -> #REF! | G35: =IFNA(VLOOKUP(B35,Datensammler!$B:$AA,24,0),"") | K35: =SUM(G35:J35) -> 0 | L35: =IFERROR('HI-LOW Berechnung'!AS34,0) -> 0 | M35: =IFERROR('HI-LOW Berechnung'!AY34,0) -> 0 | N35: =IFERROR('HI-LOW Berechnung'!BB34,0) -> 0 | O35: =IFNA(VLOOKUP(B35,Datensammler!$B:$AA,25,0),"") | S35: =SUM(O35:R35) -> 0 | T35: =IF(G35=0,"",G35/O35) -> #DIV/0! | U35: =IF(H35=0,"",H35/P35) | V35: =IF(I35="","",I35/Q35) | W35: =IF(J35="","",J35/R35) | X35: =IF(K35=0,"",K35/S35) | Y35: 30 | Z35: =IF(K35=0,0,(900-L35)/100000+(900-M35)/100000000+(900-N35)/100000000000+Y35/100000000000) -> 0 | AA35: =K35+Z35 -> 0 | AB35: 30 | AC35: =IFERROR(LARGE(AA:AA,Y35),"") -> 0 | AD35: =IF(AC35<>0,VLOOKUP(AC35,AA:AB,2,0),"") | AE35: 30 | AF35: =IF(X35="","",ROUND(X35,3)+AE35/100000) | AG35: 30 | AH35: =IFERROR(LARGE(AF:AF,Y35),"") | AI35: =IF(AH35="","",VLOOKUP(AH35,AF:AG,2,0))
A36: 31 | C36: =IF(B36="","",VLOOKUP(B36,'Mitglieder BBU'!A:N,6,0)) | D36: =IF(#REF!="","",VLOOKUP(#REF!,'Mitglieder BBU'!A:N,6,0)) -> #REF! | E36: =IF(#REF!="","",VLOOKUP(#REF!,'Mitglieder BBU'!A:N,6,0)) -> #REF! | G36: =IFNA(VLOOKUP(B36,Datensammler!$B:$AA,24,0),"") | K36: =SUM(G36:J36) -> 0 | L36: =IFERROR('HI-LOW Berechnung'!AS35,0) -> 0 | M36: =IFERROR('HI-LOW Berechnung'!AY35,0) -> 0 | N36: =IFERROR('HI-LOW Berechnung'!BB35,0) -> 0 | O36: =IFNA(VLOOKUP(B36,Datensammler!$B:$AA,25,0),"") | S36: =SUM(O36:R36) -> 0 | T36: =IF(G36=0,"",G36/O36) -> #DIV/0! | U36: =IF(H36=0,"",H36/P36) | V36: =IF(I36="","",I36/Q36) | W36: =IF(J36="","",J36/R36) | X36: =IF(K36=0,"",K36/S36) | Y36: 31 | Z36: =IF(K36=0,0,(900-L36)/100000+(900-M36)/100000000+(900-N36)/100000000000+Y36/100000000000) -> 0 | AA36: =K36+Z36 -> 0 | AB36: 31 | AC36: =IFERROR(LARGE(AA:AA,Y36),"") -> 0 | AD36: =IF(AC36<>0,VLOOKUP(AC36,AA:AB,2,0),"") | AE36: 31 | AF36: =IF(X36="","",ROUND(X36,3)+AE36/100000) | AG36: 31 | AH36: =IFERROR(LARGE(AF:AF,Y36),"") | AI36: =IF(AH36="","",VLOOKUP(AH36,AF:AG,2,0))
A37: 32 | C37: =IF(B37="","",VLOOKUP(B37,'Mitglieder BBU'!A:N,6,0)) | D37: =IF(#REF!="","",VLOOKUP(#REF!,'Mitglieder BBU'!A:N,6,0)) -> #REF! | E37: =IF(#REF!="","",VLOOKUP(#REF!,'Mitglieder BBU'!A:N,6,0)) -> #REF! | G37: =IFNA(VLOOKUP(B37,Datensammler!$B:$AA,24,0),"") | K37: =SUM(G37:J37) -> 0 | L37: =IFERROR('HI-LOW Berechnung'!AS36,0) -> 0 | M37: =IFERROR('HI-LOW Berechnung'!AY36,0) -> 0 | N37: =IFERROR('HI-LOW Berechnung'!BB36,0) -> 0 | O37: =IFNA(VLOOKUP(B37,Datensammler!$B:$AA,25,0),"") | S37: =SUM(O37:R37) -> 0 | T37: =IF(G37=0,"",G37/O37) -> #DIV/0! | U37: =IF(H37=0,"",H37/P37) | V37: =IF(I37="","",I37/Q37) | W37: =IF(J37="","",J37/R37) | X37: =IF(K37=0,"",K37/S37) | Y37: 32 | Z37: =IF(K37=0,0,(900-L37)/100000+(900-M37)/100000000+(900-N37)/100000000000+Y37/100000000000) -> 0 | AA37: =K37+Z37 -> 0 | AB37: 32 | AC37: =IFERROR(LARGE(AA:AA,Y37),"") -> 0 | AD37: =IF(AC37<>0,VLOOKUP(AC37,AA:AB,2,0),"") | AE37: 32 | AF37: =IF(X37="","",ROUND(X37,3)+AE37/100000) | AG37: 32 | AH37: =IFERROR(LARGE(AF:AF,Y37),"") | AI37: =IF(AH37="","",VLOOKUP(AH37,AF:AG,2,0))
A38: 33 | C38: =IF(B38="","",VLOOKUP(B38,'Mitglieder BBU'!A:N,6,0)) | D38: =IF(#REF!="","",VLOOKUP(#REF!,'Mitglieder BBU'!A:N,6,0)) -> #REF! | E38: =IF(#REF!="","",VLOOKUP(#REF!,'Mitglieder BBU'!A:N,6,0)) -> #REF! | G38: =IFNA(VLOOKUP(B38,Datensammler!$B:$AA,24,0),"") | K38: =SUM(G38:J38) -> 0 | L38: =IFERROR('HI-LOW Berechnung'!AS37,0) -> 0 | M38: =IFERROR('HI-LOW Berechnung'!AY37,0) -> 0 | N38: =IFERROR('HI-LOW Berechnung'!BB37,0) -> 0 | O38: =IFNA(VLOOKUP(B38,Datensammler!$B:$AA,25,0),"") | S38: =SUM(O38:R38) -> 0 | T38: =IF(G38=0,"",G38/O38) -> #DIV/0! | U38: =IF(H38=0,"",H38/P38) | V38: =IF(I38="","",I38/Q38) | W38: =IF(J38="","",J38/R38) | X38: =IF(K38=0,"",K38/S38) | Y38: 33 | Z38: =IF(K38=0,0,(900-L38)/100000+(900-M38)/100000000+(900-N38)/100000000000+Y38/100000000000) -> 0 | AA38: =K38+Z38 -> 0 | AB38: 33 | AC38: =IFERROR(LARGE(AA:AA,Y38),"") -> 0 | AD38: =IF(AC38<>0,VLOOKUP(AC38,AA:AB,2,0),"") | AE38: 33 | AF38: =IF(X38="","",ROUND(X38,3)+AE38/100000) | AG38: 33 | AH38: =IFERROR(LARGE(AF:AF,Y38),"") | AI38: =IF(AH38="","",VLOOKUP(AH38,AF:AG,2,0))
A39: 34 | C39: =IF(B39="","",VLOOKUP(B39,'Mitglieder BBU'!A:N,6,0)) | D39: =IF(#REF!="","",VLOOKUP(#REF!,'Mitglieder BBU'!A:N,6,0)) -> #REF! | E39: =IF(#REF!="","",VLOOKUP(#REF!,'Mitglieder BBU'!A:N,6,0)) -> #REF! | G39: =IFNA(VLOOKUP(B39,Datensammler!$B:$AA,24,0),"") | K39: =SUM(G39:J39) -> 0 | L39: =IFERROR('HI-LOW Berechnung'!AS38,0) -> 0 | M39: =IFERROR('HI-LOW Berechnung'!AY38,0) -> 0 | N39: =IFERROR('HI-LOW Berechnung'!BB38,0) -> 0 | O39: =IFNA(VLOOKUP(B39,Datensammler!$B:$AA,25,0),"") | S39: =SUM(O39:R39) -> 0 | T39: =IF(G39=0,"",G39/O39) -> #DIV/0! | U39: =IF(H39=0,"",H39/P39) | V39: =IF(I39="","",I39/Q39) | W39: =IF(J39="","",J39/R39) | X39: =IF(K39=0,"",K39/S39) | Y39: 34 | Z39: =IF(K39=0,0,(900-L39)/100000+(900-M39)/100000000+(900-N39)/100000000000+Y39/100000000000) -> 0 | AA39: =K39+Z39 -> 0 | AB39: 34 | AC39: =IFERROR(LARGE(AA:AA,Y39),"") -> 0 | AD39: =IF(AC39<>0,VLOOKUP(AC39,AA:AB,2,0),"") | AE39: 34 | AF39: =IF(X39="","",ROUND(X39,3)+AE39/100000) | AG39: 34 | AH39: =IFERROR(LARGE(AF:AF,Y39),"") | AI39: =IF(AH39="","",VLOOKUP(AH39,AF:AG,2,0))
... A203: 198 | C203: =IF(B203="","",VLOOKUP(B203,'Mitglieder BBU'!A:N,6,0)) | D203: =IF(#REF!="","",VLOOKUP(#REF!,'Mitglieder BBU'!A:N,6,0)) -> #REF! | E203: =IF(#REF!="","",VLOOKUP(#REF!,'Mitglieder BBU'!A:N,6,0)) -> #REF! | G203: =IFNA(VLOOKUP(B203,Datensammler!$B:$AA,24,0),"") | K203: =SUM(G203:J203) -> 0 | L203: =IFERROR('HI-LOW Berechnung'!AS202,0) | M203: =IFERROR('HI-LOW Berechnung'!AY202,0) | N203: =IFERROR('HI-LOW Berechnung'!BB202,0) | O203: =IFNA(VLOOKUP(B203,Datensammler!$B:$AA,25,0),"") | S203: =SUM(O203:R203) -> 0 | T203: =IF(G203=0,"",G203/O203) -> #DIV/0! | U203: =IF(H203=0,"",H203/P203) | V203: =IF(I203="","",I203/Q203) | W203: =IF(J203="","",J203/R203) | X203: =IF(K203=0,"",K203/S203) | Y203: 198 | Z203: =IF(K203=0,0,(900-L203)/100000+(900-M203)/100000000+(900-N203)/100000000000+Y203/100000000000) -> 0 | AA203: =K203+Z203 -> 0 | AB203: 198 | AC203: =IFERROR(LARGE(AA:AA,Y203),"") -> 0 | AD203: =IF(AC203<>0,VLOOKUP(AC203,AA:AB,2,0),"") | AE203: 198 | AF203: =IF(X203="","",ROUND(X203,3)+AE203/100000) | AG203: 198 | AH203: =IFERROR(LARGE(AF:AF,Y203),"") | AI203: =IF(AH203="","",VLOOKUP(AH203,AF:AG,2,0))
A204: 199 | G204: =IFNA(VLOOKUP(B204,Datensammler!$B:$AA,24,0),"") | K204: =SUM(G204:J204) -> 0 | L204: =IFERROR('HI-LOW Berechnung'!AS203,0) | M204: =IFERROR('HI-LOW Berechnung'!AY203,0) | N204: =IFERROR('HI-LOW Berechnung'!BB203,0) | O204: =IFNA(VLOOKUP(B204,Datensammler!$B:$AA,25,0),"") | S204: =SUM(O204:R204) -> 0 | T204: =IF(G204=0,"",G204/O204) -> #DIV/0! | U204: =IF(H204=0,"",H204/P204) | V204: =IF(I204="","",I204/Q204) | W204: =IF(J204="","",J204/R204) | X204: =IF(K204=0,"",K204/S204) | Y204: 199 | Z204: =IF(K204=0,0,(900-L204)/100000+(900-M204)/100000000+(900-N204)/100000000000+Y204/100000000000) -> 0 | AA204: =K204+Z204 -> 0 | AB204: 199 | AC204: =IFERROR(LARGE(AA:AA,Y204),"") -> 0 | AD204: =IF(AC204<>0,VLOOKUP(AC204,AA:AB,2,0),"") | AE204: 199 | AF204: =IF(X204="","",ROUND(X204,3)+AE204/100000) | AG204: 199 | AH204: =IFERROR(LARGE(AF:AF,Y204),"") | AI204: =IF(AH204="","",VLOOKUP(AH204,AF:AG,2,0))
A205: 200 | G205: =IFNA(VLOOKUP(B205,Datensammler!$B:$AA,24,0),"") | K205: =SUM(G205:J205) -> 0 | L205: =IFERROR('HI-LOW Berechnung'!AS204,0) | M205: =IFERROR('HI-LOW Berechnung'!AY204,0) | N205: =IFERROR('HI-LOW Berechnung'!BB204,0) | O205: =IFNA(VLOOKUP(B205,Datensammler!$B:$AA,25,0),"") | S205: =SUM(O205:R205) -> 0 | T205: =IF(G205=0,"",G205/O205) -> #DIV/0! | U205: =IF(H205=0,"",H205/P205) | V205: =IF(I205="","",I205/Q205) | W205: =IF(J205="","",J205/R205) | X205: =IF(K205=0,"",K205/S205) | Y205: 200 | Z205: =IF(K205=0,0,(900-L205)/100000+(900-M205)/100000000+(900-N205)/100000000000+Y205/100000000000) -> 0 | AA205: =K205+Z205 -> 0 | AB205: 200 | AC205: =IFERROR(LARGE(AA:AA,Y205),"") -> 0 | AD205: =IF(AC205<>0,VLOOKUP(AC205,AA:AB,2,0),"") | AE205: 200 | AF205: =IF(X205="","",ROUND(X205,3)+AE205/100000) | AG205: 200 | AH205: =IFERROR(LARGE(AF:AF,Y205),"") | AI205: =IF(AH205="","",VLOOKUP(AH205,AF:AG,2,0))

Sheet Optionen
A1: Allgemeine Angaben und Einstellungen
A3: Turniername: | B3: Bayerische Meisterschaft
A4: Untergruppe | B4: Frauen Einzel
A5: Saison | B5: 2026
A7: Datum von bis: | B7: 9.5 - 10.5
A10: Auswertung: | B10: John Mesch
A11: Funktion: | B11: Seniorenwart
A12: Bowlinganlage und Ort: | B12: Rottendorf
A15: Passwort:
A31: max. 400 Einzelspieler

Sheet HI-LOW Berechnung
A4: Teamnummer | B4: EDV1 | C4: Sp1-1 | D4: Sp1-2 | E4: Sp1-3 | F4: Sp1-4 | G4: Sp1-5 | H4: Sp1-6 | I4: Sp1-7 | J4: Sp1-8 | K4: Sp1-9 | L4: Sp1-10 | M4: Sp1-11 | N4: Sp1-12 | O4: Sp1-13 | P4: Sp1-14 | Q4: Sp1-15 | R4: Sp1-16 | S4: Sp1-17 | T4: Sp1-18 | U4: Ges. Sp1 | V4: Ges. Sp2 | W4: Ges. Sp3 | X4: Ges. Sp4 | Y4: Ges. Sp5 | Z4: Ges. Sp6 | AA4: Ges. Sp7 | AB4: Ges. Sp8 | AC4: Ges. Sp9 | AD4: Ges. Sp10 | AE4: Ges. Sp11 | AF4: Ges. Sp12 | AG4: Ges. Sp13 | AH4: Ges. Sp14 | AI4: Ges. Sp15 | AJ4: Ges. Sp16 | AK4: Ges. Sp17 | AL4: Ges. Sp18 | AP4: High | AQ4: Low | AS4: Highlow 1 | AU4: Spiele | AW4: High2 | AX4: Low2 | AY4: HIlow2 | AZ4: High3 | BA4: Low3 | BB4: Highlow3
A5: =Spieler!A6 -> 1 | B5: =VLOOKUP(A5,Spieler!A:F,2,0) -> 7709 | C5: =IF(B5=0,0,VLOOKUP(B5,Datensammler!B:U,3,0)) -> 131 | D5: =IF(B5=0,0,VLOOKUP(B5,Datensammler!B:U,4,0)) -> 156 | E5: =IF(B5=0,0,VLOOKUP(B5,Datensammler!B:U,5,0)) -> 123 | F5: =IF(B5=0,0,VLOOKUP(B5,Datensammler!B:U,6,0)) -> 174 | G5: =IF(B5=0,0,VLOOKUP(B5,Datensammler!B:U,7,0)) -> 132 | H5: =IF(B5=0,0,VLOOKUP(B5,Datensammler!B:U,8,0)) -> 172 | I5: =IF(B5=0,0,VLOOKUP(B5,Datensammler!B:U,9,0)) -> 183 | J5: =IF(B5=0,0,VLOOKUP(B5,Datensammler!B:U,10,0)) -> 165 | K5: =IF(B5=0,0,VLOOKUP(B5,Datensammler!B:U,11,0)) -> 120 | L5: =IF(B5=0,0,VLOOKUP(B5,Datensammler!B:U,12,0)) -> 171 | M5: =IF(B5=0,0,VLOOKUP(B5,Datensammler!B:U,13,0)) -> 143 | N5: =IF(B5=0,0,VLOOKUP(B5,Datensammler!B:U,14,0)) -> 188 | O5: =IF(B5=0,0,VLOOKUP(B5,Datensammler!B:U,15,0)) | P5: =IF(B5=0,0,VLOOKUP(B5,Datensammler!B:U,16,0)) | Q5: =IF(B5=0,0,VLOOKUP(B5,Datensammler!B:U,17,0)) | R5: =IF(B5=0,0,VLOOKUP(B5,Datensammler!B:U,18,0)) | S5: =IF(B5=0,0,VLOOKUP(B5,Datensammler!B:U,19,0)) | T5: =IF(B5=0,0,VLOOKUP(B5,Datensammler!B:U,20,0)) | U5: =C5 -> 131 | V5: =D5 -> 156 | W5: =E5 -> 123 | X5: =F5 -> 174 | Y5: =G5 -> 132 | Z5: =H5 -> 172 | AA5: =I5 -> 183 | AB5: =J5 -> 165 | ... AL5: =T5 | AP5: =IF(V5>0,LARGE(U5:AL5,1),0) -> 188 | AQ5: =IFERROR(__xludf.DUMMYFUNCTION("IF(V5>0,MIN(FILTER(U5:AL5, U5:AL5<>0)),0)"),120.0) -> 120 | AS5: =AP5-AQ5 -> 68 | AU5: =COUNTIF(C5:T5, ">0") -> 12 | AW5: =IF(X5>0,LARGE(U5:AL5,2),0) -> 183 | AX5: =IFERROR(__xludf.DUMMYFUNCTION("IF(X5>0,SMALL(FILTER(U5:AL5, U5:AL5<>0), 2),0)"),123.0) -> 123 | AY5: =IF(V5=0,0,AW5-AX5) -> 60 | AZ5: =IF(Y5>0,LARGE(U5:AL5,3),0) -> 174 | BA5: =IFERROR(__xludf.DUMMYFUNCTION("IF(Y5>0,SMALL(FILTER(U5:AL5, U5:AL5<>0), 3),0)"),131.0) -> 131 | BB5: =AZ5-BA5 -> 43
A6: =Spieler!A7 -> 2 | B6: =VLOOKUP(A6,Spieler!A:F,2,0) -> 25347 | C6: =IF(B6=0,0,VLOOKUP(B6,Datensammler!B:U,3,0)) -> 149 | D6: =IF(B6=0,0,VLOOKUP(B6,Datensammler!B:U,4,0)) -> 140 | E6: =IF(B6=0,0,VLOOKUP(B6,Datensammler!B:U,5,0)) -> 127 | F6: =IF(B6=0,0,VLOOKUP(B6,Datensammler!B:U,6,0)) -> 163 | G6: =IF(B6=0,0,VLOOKUP(B6,Datensammler!B:U,7,0)) -> 121 | H6: =IF(B6=0,0,VLOOKUP(B6,Datensammler!B:U,8,0)) -> 116 | I6: =IF(B6=0,0,VLOOKUP(B6,Datensammler!B:U,9,0)) -> 133 | J6: =IF(B6=0,0,VLOOKUP(B6,Datensammler!B:U,10,0)) -> 132 | K6: =IF(B6=0,0,VLOOKUP(B6,Datensammler!B:U,11,0)) -> 120 | L6: =IF(B6=0,0,VLOOKUP(B6,Datensammler!B:U,12,0)) -> 151 | M6: =IF(B6=0,0,VLOOKUP(B6,Datensammler!B:U,13,0)) -> 153 | N6: =IF(B6=0,0,VLOOKUP(B6,Datensammler!B:U,14,0)) -> 145 | O6: =IF(B6=0,0,VLOOKUP(B6,Datensammler!B:U,15,0)) | P6: =IF(B6=0,0,VLOOKUP(B6,Datensammler!B:U,16,0)) | Q6: =IF(B6=0,0,VLOOKUP(B6,Datensammler!B:U,17,0)) | R6: =IF(B6=0,0,VLOOKUP(B6,Datensammler!B:U,18,0)) | S6: =IF(B6=0,0,VLOOKUP(B6,Datensammler!B:U,19,0)) | T6: =IF(B6=0,0,VLOOKUP(B6,Datensammler!B:U,20,0)) | U6: =C6 -> 149 | V6: =D6 -> 140 | W6: =E6 -> 127 | X6: =F6 -> 163 | Y6: =G6 -> 121 | Z6: =H6 -> 116 | AA6: =I6 -> 133 | AB6: =J6 -> 132 | ... AL6: =T6 | AP6: =IF(V6>0,LARGE(U6:AL6,1),0) -> 163 | AQ6: =IFERROR(__xludf.DUMMYFUNCTION("IF(V6>0,MIN(FILTER(U6:AL6, U6:AL6<>0)),0)"),116.0) -> 116 | AS6: =AP6-AQ6 -> 47 | AU6: =COUNTIF(C6:T6, ">0") -> 12 | AW6: =IF(X6>0,LARGE(U6:AL6,2),0) -> 153 | AX6: =IFERROR(__xludf.DUMMYFUNCTION("IF(X6>0,SMALL(FILTER(U6:AL6, U6:AL6<>0), 2),0)"),120.0) -> 120 | AY6: =IF(V6=0,0,AW6-AX6) -> 33 | AZ6: =IF(Y6>0,LARGE(U6:AL6,3),0) -> 151 | BA6: =IFERROR(__xludf.DUMMYFUNCTION("IF(Y6>0,SMALL(FILTER(U6:AL6, U6:AL6<>0), 3),0)"),121.0) -> 121 | BB6: =AZ6-BA6 -> 30
A7: =Spieler!A8 -> 3 | B7: =VLOOKUP(A7,Spieler!A:F,2,0) -> 7974 | C7: =IF(B7=0,0,VLOOKUP(B7,Datensammler!B:U,3,0)) -> 142 | D7: =IF(B7=0,0,VLOOKUP(B7,Datensammler!B:U,4,0)) -> 104 | E7: =IF(B7=0,0,VLOOKUP(B7,Datensammler!B:U,5,0)) -> 159 | F7: =IF(B7=0,0,VLOOKUP(B7,Datensammler!B:U,6,0)) -> 119 | G7: =IF(B7=0,0,VLOOKUP(B7,Datensammler!B:U,7,0)) -> 130 | H7: =IF(B7=0,0,VLOOKUP(B7,Datensammler!B:U,8,0)) -> 165 | I7: =IF(B7=0,0,VLOOKUP(B7,Datensammler!B:U,9,0)) -> 122 | J7: =IF(B7=0,0,VLOOKUP(B7,Datensammler!B:U,10,0)) -> 126 | K7: =IF(B7=0,0,VLOOKUP(B7,Datensammler!B:U,11,0)) -> 126 | L7: =IF(B7=0,0,VLOOKUP(B7,Datensammler!B:U,12,0)) -> 151 | M7: =IF(B7=0,0,VLOOKUP(B7,Datensammler!B:U,13,0)) -> 136 | N7: =IF(B7=0,0,VLOOKUP(B7,Datensammler!B:U,14,0)) -> 116 | O7: =IF(B7=0,0,VLOOKUP(B7,Datensammler!B:U,15,0)) | P7: =IF(B7=0,0,VLOOKUP(B7,Datensammler!B:U,16,0)) | Q7: =IF(B7=0,0,VLOOKUP(B7,Datensammler!B:U,17,0)) | R7: =IF(B7=0,0,VLOOKUP(B7,Datensammler!B:U,18,0)) | S7: =IF(B7=0,0,VLOOKUP(B7,Datensammler!B:U,19,0)) | T7: =IF(B7=0,0,VLOOKUP(B7,Datensammler!B:U,20,0)) | U7: =C7 -> 142 | V7: =D7 -> 104 | W7: =E7 -> 159 | X7: =F7 -> 119 | Y7: =G7 -> 130 | Z7: =H7 -> 165 | AA7: =I7 -> 122 | AB7: =J7 -> 126 | ... AL7: =T7 | AP7: =IF(V7>0,LARGE(U7:AL7,1),0) -> 165 | AQ7: =IFERROR(__xludf.DUMMYFUNCTION("IF(V7>0,MIN(FILTER(U7:AL7, U7:AL7<>0)),0)"),104.0) -> 104 | AS7: =AP7-AQ7 -> 61 | AU7: =COUNTIF(C7:T7, ">0") -> 12 | AW7: =IF(X7>0,LARGE(U7:AL7,2),0) -> 159 | AX7: =IFERROR(__xludf.DUMMYFUNCTION("IF(X7>0,SMALL(FILTER(U7:AL7, U7:AL7<>0), 2),0)"),116.0) -> 116 | AY7: =IF(V7=0,0,AW7-AX7) -> 43 | AZ7: =IF(Y7>0,LARGE(U7:AL7,3),0) -> 151 | BA7: =IFERROR(__xludf.DUMMYFUNCTION("IF(Y7>0,SMALL(FILTER(U7:AL7, U7:AL7<>0), 3),0)"),119.0) -> 119 | BB7: =AZ7-BA7 -> 32
A8: =Spieler!A9 -> 4 | B8: =VLOOKUP(A8,Spieler!A:F,2,0) -> 25329 | C8: =IF(B8=0,0,VLOOKUP(B8,Datensammler!B:U,3,0)) -> 176 | D8: =IF(B8=0,0,VLOOKUP(B8,Datensammler!B:U,4,0)) -> 207 | E8: =IF(B8=0,0,VLOOKUP(B8,Datensammler!B:U,5,0)) -> 158 | F8: =IF(B8=0,0,VLOOKUP(B8,Datensammler!B:U,6,0)) -> 152 | G8: =IF(B8=0,0,VLOOKUP(B8,Datensammler!B:U,7,0)) -> 186 | H8: =IF(B8=0,0,VLOOKUP(B8,Datensammler!B:U,8,0)) -> 149 | I8: =IF(B8=0,0,VLOOKUP(B8,Datensammler!B:U,9,0)) -> 149 | J8: =IF(B8=0,0,VLOOKUP(B8,Datensammler!B:U,10,0)) -> 155 | K8: =IF(B8=0,0,VLOOKUP(B8,Datensammler!B:U,11,0)) -> 140 | L8: =IF(B8=0,0,VLOOKUP(B8,Datensammler!B:U,12,0)) -> 169 | M8: =IF(B8=0,0,VLOOKUP(B8,Datensammler!B:U,13,0)) -> 159 | N8: =IF(B8=0,0,VLOOKUP(B8,Datensammler!B:U,14,0)) -> 183 | O8: =IF(B8=0,0,VLOOKUP(B8,Datensammler!B:U,15,0)) | P8: =IF(B8=0,0,VLOOKUP(B8,Datensammler!B:U,16,0)) | Q8: =IF(B8=0,0,VLOOKUP(B8,Datensammler!B:U,17,0)) | R8: =IF(B8=0,0,VLOOKUP(B8,Datensammler!B:U,18,0)) | S8: =IF(B8=0,0,VLOOKUP(B8,Datensammler!B:U,19,0)) | T8: =IF(B8=0,0,VLOOKUP(B8,Datensammler!B:U,20,0)) | U8: =C8 -> 176 | V8: =D8 -> 207 | W8: =E8 -> 158 | X8: =F8 -> 152 | Y8: =G8 -> 186 | Z8: =H8 -> 149 | AA8: =I8 -> 149 | AB8: =J8 -> 155 | ... AL8: =T8 | AP8: =IF(V8>0,LARGE(U8:AL8,1),0) -> 207 | AQ8: =IFERROR(__xludf.DUMMYFUNCTION("IF(V8>0,MIN(FILTER(U8:AL8, U8:AL8<>0)),0)"),140.0) -> 140 | AS8: =AP8-AQ8 -> 67 | AU8: =COUNTIF(C8:T8, ">0") -> 12 | AW8: =IF(X8>0,LARGE(U8:AL8,2),0) -> 186 | AX8: =IFERROR(__xludf.DUMMYFUNCTION("IF(X8>0,SMALL(FILTER(U8:AL8, U8:AL8<>0), 2),0)"),149.0) -> 149 | AY8: =IF(V8=0,0,AW8-AX8) -> 37 | AZ8: =IF(Y8>0,LARGE(U8:AL8,3),0) -> 183 | BA8: =IFERROR(__xludf.DUMMYFUNCTION("IF(Y8>0,SMALL(FILTER(U8:AL8, U8:AL8<>0), 3),0)"),149.0) -> 149 | BB8: =AZ8-BA8 -> 34
A9: =Spieler!A10 -> 5 | B9: =VLOOKUP(A9,Spieler!A:F,2,0) -> 38934 | C9: =IF(B9=0,0,VLOOKUP(B9,Datensammler!B:U,3,0)) -> 134 | D9: =IF(B9=0,0,VLOOKUP(B9,Datensammler!B:U,4,0)) -> 132 | E9: =IF(B9=0,0,VLOOKUP(B9,Datensammler!B:U,5,0)) -> 120 | F9: =IF(B9=0,0,VLOOKUP(B9,Datensammler!B:U,6,0)) -> 136 | G9: =IF(B9=0,0,VLOOKUP(B9,Datensammler!B:U,7,0)) -> 160 | H9: =IF(B9=0,0,VLOOKUP(B9,Datensammler!B:U,8,0)) -> 148 | I9: =IF(B9=0,0,VLOOKUP(B9,Datensammler!B:U,9,0)) -> 134 | J9: =IF(B9=0,0,VLOOKUP(B9,Datensammler!B:U,10,0)) -> 145 | K9: =IF(B9=0,0,VLOOKUP(B9,Datensammler!B:U,11,0)) -> 125 | L9: =IF(B9=0,0,VLOOKUP(B9,Datensammler!B:U,12,0)) -> 123 | M9: =IF(B9=0,0,VLOOKUP(B9,Datensammler!B:U,13,0)) -> 191 | N9: =IF(B9=0,0,VLOOKUP(B9,Datensammler!B:U,14,0)) -> 153 | O9: =IF(B9=0,0,VLOOKUP(B9,Datensammler!B:U,15,0)) | P9: =IF(B9=0,0,VLOOKUP(B9,Datensammler!B:U,16,0)) | Q9: =IF(B9=0,0,VLOOKUP(B9,Datensammler!B:U,17,0)) | R9: =IF(B9=0,0,VLOOKUP(B9,Datensammler!B:U,18,0)) | S9: =IF(B9=0,0,VLOOKUP(B9,Datensammler!B:U,19,0)) | T9: =IF(B9=0,0,VLOOKUP(B9,Datensammler!B:U,20,0)) | U9: =C9 -> 134 | V9: =D9 -> 132 | W9: =E9 -> 120 | X9: =F9 -> 136 | Y9: =G9 -> 160 | Z9: =H9 -> 148 | AA9: =I9 -> 134 | AB9: =J9 -> 145 | ... AL9: =T9 | AP9: =IF(V9>0,LARGE(U9:AL9,1),0) -> 191 | AQ9: =IFERROR(__xludf.DUMMYFUNCTION("IF(V9>0,MIN(FILTER(U9:AL9, U9:AL9<>0)),0)"),120.0) -> 120 | AS9: =AP9-AQ9 -> 71 | AU9: =COUNTIF(C9:T9, ">0") -> 12 | AW9: =IF(X9>0,LARGE(U9:AL9,2),0) -> 160 | AX9: =IFERROR(__xludf.DUMMYFUNCTION("IF(X9>0,SMALL(FILTER(U9:AL9, U9:AL9<>0), 2),0)"),123.0) -> 123 | AY9: =IF(V9=0,0,AW9-AX9) -> 37 | AZ9: =IF(Y9>0,LARGE(U9:AL9,3),0) -> 153 | BA9: =IFERROR(__xludf.DUMMYFUNCTION("IF(Y9>0,SMALL(FILTER(U9:AL9, U9:AL9<>0), 3),0)"),125.0) -> 125 | BB9: =AZ9-BA9 -> 28
A10: =Spieler!A11 -> 6 | B10: =VLOOKUP(A10,Spieler!A:F,2,0) -> 16595 | C10: =IF(B10=0,0,VLOOKUP(B10,Datensammler!B:U,3,0)) -> 177 | D10: =IF(B10=0,0,VLOOKUP(B10,Datensammler!B:U,4,0)) -> 162 | E10: =IF(B10=0,0,VLOOKUP(B10,Datensammler!B:U,5,0)) -> 196 | F10: =IF(B10=0,0,VLOOKUP(B10,Datensammler!B:U,6,0)) -> 136 | G10: =IF(B10=0,0,VLOOKUP(B10,Datensammler!B:U,7,0)) -> 165 | H10: =IF(B10=0,0,VLOOKUP(B10,Datensammler!B:U,8,0)) -> 153 | I10: =IF(B10=0,0,VLOOKUP(B10,Datensammler!B:U,9,0)) -> 141 | J10: =IF(B10=0,0,VLOOKUP(B10,Datensammler!B:U,10,0)) -> 166 | K10: =IF(B10=0,0,VLOOKUP(B10,Datensammler!B:U,11,0)) -> 164 | L10: =IF(B10=0,0,VLOOKUP(B10,Datensammler!B:U,12,0)) -> 194 | M10: =IF(B10=0,0,VLOOKUP(B10,Datensammler!B:U,13,0)) -> 191 | N10: =IF(B10=0,0,VLOOKUP(B10,Datensammler!B:U,14,0)) -> 152 | O10: =IF(B10=0,0,VLOOKUP(B10,Datensammler!B:U,15,0)) | P10: =IF(B10=0,0,VLOOKUP(B10,Datensammler!B:U,16,0)) | Q10: =IF(B10=0,0,VLOOKUP(B10,Datensammler!B:U,17,0)) | R10: =IF(B10=0,0,VLOOKUP(B10,Datensammler!B:U,18,0)) | S10: =IF(B10=0,0,VLOOKUP(B10,Datensammler!B:U,19,0)) | T10: =IF(B10=0,0,VLOOKUP(B10,Datensammler!B:U,20,0)) | U10: =C10 -> 177 | V10: =D10 -> 162 | W10: =E10 -> 196 | X10: =F10 -> 136 | Y10: =G10 -> 165 | Z10: =H10 -> 153 | AA10: =I10 -> 141 | AB10: =J10 -> 166 | ... AL10: =T10 | AP10: =IF(V10>0,LARGE(U10:AL10,1),0) -> 196 | AQ10: =IFERROR(__xludf.DUMMYFUNCTION("IF(V10>0,MIN(FILTER(U10:AL10, U10:AL10<>0)),0)"),136.0) -> 136 | AS10: =AP10-AQ10 -> 60 | AU10: =COUNTIF(C10:T10, ">0") -> 12 | AW10: =IF(X10>0,LARGE(U10:AL10,2),0) -> 194 | AX10: =IFERROR(__xludf.DUMMYFUNCTION("IF(X10>0,SMALL(FILTER(U10:AL10, U10:AL10<>0), 2),0)"),141.0) -> 141 | AY10: =IF(V10=0,0,AW10-AX10) -> 53 | AZ10: =IF(Y10>0,LARGE(U10:AL10,3),0) -> 191 | BA10: =IFERROR(__xludf.DUMMYFUNCTION("IF(Y10>0,SMALL(FILTER(U10:AL10, U10:AL10<>0), 3),0)"),152.0) -> 152 | BB10: =AZ10-BA10 -> 39
A11: =Spieler!A12 -> 7 | B11: =VLOOKUP(A11,Spieler!A:F,2,0) -> 16594 | C11: =IF(B11=0,0,VLOOKUP(B11,Datensammler!B:U,3,0)) -> 200 | D11: =IF(B11=0,0,VLOOKUP(B11,Datensammler!B:U,4,0)) -> 152 | E11: =IF(B11=0,0,VLOOKUP(B11,Datensammler!B:U,5,0)) -> 161 | F11: =IF(B11=0,0,VLOOKUP(B11,Datensammler!B:U,6,0)) -> 178 | G11: =IF(B11=0,0,VLOOKUP(B11,Datensammler!B:U,7,0)) -> 159 | H11: =IF(B11=0,0,VLOOKUP(B11,Datensammler!B:U,8,0)) -> 170 | I11: =IF(B11=0,0,VLOOKUP(B11,Datensammler!B:U,9,0)) -> 172 | J11: =IF(B11=0,0,VLOOKUP(B11,Datensammler!B:U,10,0)) -> 145 | K11: =IF(B11=0,0,VLOOKUP(B11,Datensammler!B:U,11,0)) -> 144 | L11: =IF(B11=0,0,VLOOKUP(B11,Datensammler!B:U,12,0)) -> 169 | M11: =IF(B11=0,0,VLOOKUP(B11,Datensammler!B:U,13,0)) -> 153 | N11: =IF(B11=0,0,VLOOKUP(B11,Datensammler!B:U,14,0)) -> 156 | O11: =IF(B11=0,0,VLOOKUP(B11,Datensammler!B:U,15,0)) | P11: =IF(B11=0,0,VLOOKUP(B11,Datensammler!B:U,16,0)) | Q11: =IF(B11=0,0,VLOOKUP(B11,Datensammler!B:U,17,0)) | R11: =IF(B11=0,0,VLOOKUP(B11,Datensammler!B:U,18,0)) | S11: =IF(B11=0,0,VLOOKUP(B11,Datensammler!B:U,19,0)) | T11: =IF(B11=0,0,VLOOKUP(B11,Datensammler!B:U,20,0)) | U11: =C11 -> 200 | V11: =D11 -> 152 | W11: =E11 -> 161 | X11: =F11 -> 178 | Y11: =G11 -> 159 | Z11: =H11 -> 170 | AA11: =I11 -> 172 | AB11: =J11 -> 145 | ... AL11: =T11 | AP11: =IF(V11>0,LARGE(U11:AL11,1),0) -> 200 | AQ11: =IFERROR(__xludf.DUMMYFUNCTION("IF(V11>0,MIN(FILTER(U11:AL11, U11:AL11<>0)),0)"),144.0) -> 144 | AS11: =AP11-AQ11 -> 56 | AU11: =COUNTIF(C11:T11, ">0") -> 12 | AW11: =IF(X11>0,LARGE(U11:AL11,2),0) -> 178 | AX11: =IFERROR(__xludf.DUMMYFUNCTION("IF(X11>0,SMALL(FILTER(U11:AL11, U11:AL11<>0), 2),0)"),145.0) -> 145 | AY11: =IF(V11=0,0,AW11-AX11) -> 33 | AZ11: =IF(Y11>0,LARGE(U11:AL11,3),0) -> 172 | BA11: =IFERROR(__xludf.DUMMYFUNCTION("IF(Y11>0,SMALL(FILTER(U11:AL11, U11:AL11<>0), 3),0)"),152.0) -> 152 | BB11: =AZ11-BA11 -> 20
A12: =Spieler!A13 -> 8 | B12: =VLOOKUP(A12,Spieler!A:F,2,0) -> 38931 | C12: =IF(B12=0,0,VLOOKUP(B12,Datensammler!B:U,3,0)) -> 153 | D12: =IF(B12=0,0,VLOOKUP(B12,Datensammler!B:U,4,0)) -> 202 | E12: =IF(B12=0,0,VLOOKUP(B12,Datensammler!B:U,5,0)) -> 141 | F12: =IF(B12=0,0,VLOOKUP(B12,Datensammler!B:U,6,0)) -> 141 | G12: =IF(B12=0,0,VLOOKUP(B12,Datensammler!B:U,7,0)) -> 148 | H12: =IF(B12=0,0,VLOOKUP(B12,Datensammler!B:U,8,0)) -> 186 | I12: =IF(B12=0,0,VLOOKUP(B12,Datensammler!B:U,9,0)) -> 142 | J12: =IF(B12=0,0,VLOOKUP(B12,Datensammler!B:U,10,0)) -> 185 | K12: =IF(B12=0,0,VLOOKUP(B12,Datensammler!B:U,11,0)) -> 149 | L12: =IF(B12=0,0,VLOOKUP(B12,Datensammler!B:U,12,0)) -> 179 | M12: =IF(B12=0,0,VLOOKUP(B12,Datensammler!B:U,13,0)) -> 160 | N12: =IF(B12=0,0,VLOOKUP(B12,Datensammler!B:U,14,0)) -> 169 | O12: =IF(B12=0,0,VLOOKUP(B12,Datensammler!B:U,15,0)) | P12: =IF(B12=0,0,VLOOKUP(B12,Datensammler!B:U,16,0)) | Q12: =IF(B12=0,0,VLOOKUP(B12,Datensammler!B:U,17,0)) | R12: =IF(B12=0,0,VLOOKUP(B12,Datensammler!B:U,18,0)) | S12: =IF(B12=0,0,VLOOKUP(B12,Datensammler!B:U,19,0)) | T12: =IF(B12=0,0,VLOOKUP(B12,Datensammler!B:U,20,0)) | U12: =C12 -> 153 | V12: =D12 -> 202 | W12: =E12 -> 141 | X12: =F12 -> 141 | Y12: =G12 -> 148 | Z12: =H12 -> 186 | AA12: =I12 -> 142 | AB12: =J12 -> 185 | ... AL12: =T12 | AP12: =IF(V12>0,LARGE(U12:AL12,1),0) -> 202 | AQ12: =IFERROR(__xludf.DUMMYFUNCTION("IF(V12>0,MIN(FILTER(U12:AL12, U12:AL12<>0)),0)"),141.0) -> 141 | AS12: =AP12-AQ12 -> 61 | AU12: =COUNTIF(C12:T12, ">0") -> 12 | AW12: =IF(X12>0,LARGE(U12:AL12,2),0) -> 186 | AX12: =IFERROR(__xludf.DUMMYFUNCTION("IF(X12>0,SMALL(FILTER(U12:AL12, U12:AL12<>0), 2),0)"),141.0) -> 141 | AY12: =IF(V12=0,0,AW12-AX12) -> 45 | AZ12: =IF(Y12>0,LARGE(U12:AL12,3),0) -> 185 | BA12: =IFERROR(__xludf.DUMMYFUNCTION("IF(Y12>0,SMALL(FILTER(U12:AL12, U12:AL12<>0), 3),0)"),142.0) -> 142 | BB12: =AZ12-BA12 -> 43
A13: =Spieler!A14 -> 9 | B13: =VLOOKUP(A13,Spieler!A:F,2,0) -> 38045 | C13: =IF(B13=0,0,VLOOKUP(B13,Datensammler!B:U,3,0)) -> 201 | D13: =IF(B13=0,0,VLOOKUP(B13,Datensammler!B:U,4,0)) -> 223 | E13: =IF(B13=0,0,VLOOKUP(B13,Datensammler!B:U,5,0)) -> 196 | F13: =IF(B13=0,0,VLOOKUP(B13,Datensammler!B:U,6,0)) -> 191 | G13: =IF(B13=0,0,VLOOKUP(B13,Datensammler!B:U,7,0)) -> 181 | H13: =IF(B13=0,0,VLOOKUP(B13,Datensammler!B:U,8,0)) -> 208 | I13: =IF(B13=0,0,VLOOKUP(B13,Datensammler!B:U,9,0)) -> 198 | J13: =IF(B13=0,0,VLOOKUP(B13,Datensammler!B:U,10,0)) -> 234 | K13: =IF(B13=0,0,VLOOKUP(B13,Datensammler!B:U,11,0)) -> 170 | L13: =IF(B13=0,0,VLOOKUP(B13,Datensammler!B:U,12,0)) -> 219 | M13: =IF(B13=0,0,VLOOKUP(B13,Datensammler!B:U,13,0)) -> 214 | N13: =IF(B13=0,0,VLOOKUP(B13,Datensammler!B:U,14,0)) -> 206 | O13: =IF(B13=0,0,VLOOKUP(B13,Datensammler!B:U,15,0)) | P13: =IF(B13=0,0,VLOOKUP(B13,Datensammler!B:U,16,0)) | Q13: =IF(B13=0,0,VLOOKUP(B13,Datensammler!B:U,17,0)) | R13: =IF(B13=0,0,VLOOKUP(B13,Datensammler!B:U,18,0)) | S13: =IF(B13=0,0,VLOOKUP(B13,Datensammler!B:U,19,0)) | T13: =IF(B13=0,0,VLOOKUP(B13,Datensammler!B:U,20,0)) | U13: =C13 -> 201 | V13: =D13 -> 223 | W13: =E13 -> 196 | X13: =F13 -> 191 | Y13: =G13 -> 181 | Z13: =H13 -> 208 | AA13: =I13 -> 198 | AB13: =J13 -> 234 | ... AL13: =T13 | AP13: =IF(V13>0,LARGE(U13:AL13,1),0) -> 234 | AQ13: =IFERROR(__xludf.DUMMYFUNCTION("IF(V13>0,MIN(FILTER(U13:AL13, U13:AL13<>0)),0)"),170.0) -> 170 | AS13: =AP13-AQ13 -> 64 | AU13: =COUNTIF(C13:T13, ">0") -> 12 | AW13: =IF(X13>0,LARGE(U13:AL13,2),0) -> 223 | AX13: =IFERROR(__xludf.DUMMYFUNCTION("IF(X13>0,SMALL(FILTER(U13:AL13, U13:AL13<>0), 2),0)"),181.0) -> 181 | AY13: =IF(V13=0,0,AW13-AX13) -> 42 | AZ13: =IF(Y13>0,LARGE(U13:AL13,3),0) -> 219 | BA13: =IFERROR(__xludf.DUMMYFUNCTION("IF(Y13>0,SMALL(FILTER(U13:AL13, U13:AL13<>0), 3),0)"),191.0) -> 191 | BB13: =AZ13-BA13 -> 28
A14: =Spieler!A15 -> 10 | B14: =VLOOKUP(A14,Spieler!A:F,2,0) -> 38876 | C14: =IF(B14=0,0,VLOOKUP(B14,Datensammler!B:U,3,0)) -> 125 | D14: =IF(B14=0,0,VLOOKUP(B14,Datensammler!B:U,4,0)) -> 140 | E14: =IF(B14=0,0,VLOOKUP(B14,Datensammler!B:U,5,0)) -> 157 | F14: =IF(B14=0,0,VLOOKUP(B14,Datensammler!B:U,6,0)) -> 211 | G14: =IF(B14=0,0,VLOOKUP(B14,Datensammler!B:U,7,0)) -> 175 | H14: =IF(B14=0,0,VLOOKUP(B14,Datensammler!B:U,8,0)) -> 116 | I14: =IF(B14=0,0,VLOOKUP(B14,Datensammler!B:U,9,0)) -> 146 | J14: =IF(B14=0,0,VLOOKUP(B14,Datensammler!B:U,10,0)) -> 157 | K14: =IF(B14=0,0,VLOOKUP(B14,Datensammler!B:U,11,0)) -> 138 | L14: =IF(B14=0,0,VLOOKUP(B14,Datensammler!B:U,12,0)) -> 157 | M14: =IF(B14=0,0,VLOOKUP(B14,Datensammler!B:U,13,0)) -> 144 | N14: =IF(B14=0,0,VLOOKUP(B14,Datensammler!B:U,14,0)) -> 157 | O14: =IF(B14=0,0,VLOOKUP(B14,Datensammler!B:U,15,0)) | P14: =IF(B14=0,0,VLOOKUP(B14,Datensammler!B:U,16,0)) | Q14: =IF(B14=0,0,VLOOKUP(B14,Datensammler!B:U,17,0)) | R14: =IF(B14=0,0,VLOOKUP(B14,Datensammler!B:U,18,0)) | S14: =IF(B14=0,0,VLOOKUP(B14,Datensammler!B:U,19,0)) | T14: =IF(B14=0,0,VLOOKUP(B14,Datensammler!B:U,20,0)) | U14: =C14 -> 125 | V14: =D14 -> 140 | W14: =E14 -> 157 | X14: =F14 -> 211 | Y14: =G14 -> 175 | Z14: =H14 -> 116 | AA14: =I14 -> 146 | AB14: =J14 -> 157 | ... AL14: =T14 | AP14: =IF(V14>0,LARGE(U14:AL14,1),0) -> 211 | AQ14: =IFERROR(__xludf.DUMMYFUNCTION("IF(V14>0,MIN(FILTER(U14:AL14, U14:AL14<>0)),0)"),116.0) -> 116 | AS14: =AP14-AQ14 -> 95 | AU14: =COUNTIF(C14:T14, ">0") -> 12 | AW14: =IF(X14>0,LARGE(U14:AL14,2),0) -> 175 | AX14: =IFERROR(__xludf.DUMMYFUNCTION("IF(X14>0,SMALL(FILTER(U14:AL14, U14:AL14<>0), 2),0)"),125.0) -> 125 | AY14: =IF(V14=0,0,AW14-AX14) -> 50 | AZ14: =IF(Y14>0,LARGE(U14:AL14,3),0) -> 157 | BA14: =IFERROR(__xludf.DUMMYFUNCTION("IF(Y14>0,SMALL(FILTER(U14:AL14, U14:AL14<>0), 3),0)"),138.0) -> 138 | BB14: =AZ14-BA14 -> 19
